Workbook

Sheet MAIO
A1: CRE | C1: NOME FANTASIA | D1: MANTENEDORA | E1: ENDEREÇO | F1: BAIRRO | G1: META | H1: FAIXA ETÁRIA | I1: BI | K1: B II | M1: M I | O1: M II | Q1: TOTAL ALUNOS | R1: TOTAL INCLUÍDOS | S1: REDUÇÃO DE VAGAS POR INCLUÍDOS EM BERÇÁRIO | T1: REDUÇÃO DE VAGAS POR INCLUÍDOS EM MATERNAL | U1: VAGAS | V1: EXCENDENTE | W1: OBS
I2: Alunos | J2: Incluídos | K2: Alunos | L2: Incluídos | M2: Alunos | N2: Incluídos | O2: Alunos | P2: Incluídos
A4: 1ª | B4: 1 | C4: Casa Maternal Coração De Mãe | D4: Instituto Missionário Comunhão E Participação | E4: Rua Conceição, Nº 01 | F4: Rio Comprido | G4: 40 | H4: 2 anos | M4: 20 | O4: 19 | P4: 1 | Q4: =SUM(I4,K4,M4,O4) -> 39 | R4: =SUM(J4,L4,N4,P4) -> 1 | S4: =IF((J4+L4)>=1,2,0) -> 0 | T4: =IF((N4+P4)>=1,2,0) -> 2 | U4: =SUM(G4-Q4-((S4*1)+(T4*1))) -> -1 | V4: =IF(U4<0,U4,0) -> -1
B5: 2 | C5: Creche Cantinho Feliz De Santa Teresa | D5: Instituto Trilho | E5: Rua Almirante Alexandrina, 2495 | F5: Santa Teresa | G5: 50 | H5: 2 anos | M5: 24 | O5: 25 | Q5: =SUM(I5,K5,M5,O5) -> 49 | R5: =SUM(J5,L5,N5,P5) -> 0 | S5: =IF((J5+L5)>=1,2,0) -> 0 | T5: =IF((N5+P5)>=1,2,0) -> 0 | U5: =SUM(G5-Q5-((S5*1)+(T5*1))) -> 1 | V5: =IF(U5<0,U5,0) -> 0
B6: 3 | C6: Creche Tuiuti | D6: Núcleo De Ação Comunitária E Desenvolvimento Social - Nacodes | E6: Rua São Luiz Gonzaga, Nº 1612-Fundos | F6: Benfica | G6: 147 | H6: 1 ano | K6: 44 | M6: 57 | O6: 46 | Q6: =SUM(I6,K6,M6,O6) -> 147 | R6: =SUM(J6,L6,N6,P6) -> 0 | S6: =IF((J6+L6)>=1,2,0) -> 0 | T6: =IF((N6+P6)>=1,2,0) -> 0 | U6: =SUM(G6-Q6-((S6*1)+(T6*1))) -> 0 | V6: =IF(U6<0,U6,0) -> 0
B7: 4 | C7: Educandário N. Srª De Nazaré | D7: Congregação Das Pequenas Irmãs Da Divina Providência | E7: Rua Doutor Agra, Nº 115 | F7: Catumbi | G7: 30 | M7: 15 | N7: 2 | O7: 14 | Q7: =SUM(I7,K7,M7,O7) -> 29 | R7: =SUM(J7,L7,N7,P7) -> 2 | S7: =IF((J7+L7)>=1,2,0) -> 0 | T7: =IF((N7+P7)>=1,2,0) -> 2 | U7: =SUM(G7-Q7-((S7*1)+(T7*1))) -> -1 | V7: =IF(U7<0,U7,0) -> -1
B8: 5 | C8: Creche Comunitária Preventório Rainha Dona Amélia | E8: Rua Cerqueira, 16 | F8: Paquetá | G8: 45 | H8: 2 anos | M8: 11 | O8: 13 | Q8: =SUM(I8,K8,M8,O8) -> 24 | R8: =SUM(J8,L8,N8,P8) -> 0 | S8: =IF((J8+L8)>=1,2,0) -> 0 | T8: =IF((N8+P8)>=1,2,0) -> 0 | U8: =SUM(G8-Q8-((S8*1)+(T8*1))) -> 21 | V8: =IF(U8<0,U8,0) -> 0 | W8: 3º chamamento
A10: 2ª | B10: 1 | C10: Abrigo Teresa De Jesus | D10: Abrigo Teresa De Jesus | E10: Rua Ibituruna, 53 | F10: Tijuca | G10: 96 | H10: 6 meses | M10: 45 | N10: 1 | O10: 47 | P10: 3 | Q10: =SUM(I10,K10,M10,O10) -> 92 | R10: =SUM(J10,L10,N10,P10) -> 4 | S10: =IF((J10+L10)>=1,2,0) -> 0 | T10: =IF((N10+P10)>=1,2,0) -> 2 | U10: =SUM(G10-Q10-((S10*1)+(T10*1))) -> 2 | V10: =IF(U10<0,U10,0) -> 0
B11: 2 | C11: Ação Social Padre Anchieta - Aspa | D11: Ação Social Padre Anchieta - Aspa | E11: Travessa Luz, 13 | F11: Rocinha | G11: 179 | H11: 6 meses | I11: 23 | J11: 1 | K11: 24 | M11: 64 | O11: 66 | P11: 1 | Q11: =SUM(I11,K11,M11,O11) -> 177 | R11: =SUM(J11,L11,N11,P11) -> 2 | S11: =IF((J11+L11)>=1,2,0) -> 2 | T11: =IF((N11+P11)>=1,2,0) -> 2 | U11: =SUM(G11-Q11-((S11*1)+(T11*1))) -> -2 | V11: =IF(U11<0,U11,0) -> -2
B12: 3 | C12: Casa Da Criança | D12: Casa Da Criança | E12: Rua Fernandes Guimarães, 85 | F12: Botafogo | G12: 192 | H12: 6 meses | I12: 27 | K12: 23 | M12: 68 | O12: 68 | Q12: =SUM(I12,K12,M12,O12) -> 186 | R12: =SUM(J12,L12,N12,P12) -> 0 | S12: =IF((J12+L12)>=1,2,0) -> 0 | T12: =IF((N12+P12)>=1,2,0) -> 0 | U12: =SUM(G12-Q12-((S12*1)+(T12*1))) -> 6 | V12: =IF(U12<0,U12,0) -> 0
B13: 4 | C13: Casa Espírita Cristã Maria De Nazaré | D13: Casa Espírita Cristã Maria De Nazaré | E13: Estr. Da Gávea, 262, Quarteirão 21, R. Um S/Nº | F13: Rocinha | G13: 120 | H13: 0 ano | I13: 18 | K13: 21 | M13: 38 | O13: 40 | Q13: =SUM(I13,K13,M13,O13) -> 117 | R13: =SUM(J13,L13,N13,P13) -> 0 | S13: =IF((J13+L13)>=1,2,0) -> 0 | T13: =IF((N13+P13)>=1,2,0) -> 0 | U13: =SUM(G13-Q13-((S13*1)+(T13*1))) -> 3 | V13: =IF(U13<0,U13,0) -> 0
B14: 5 | C14: Casa Maternal Mello Mattos | D14: Associação Tutelar De Menores | E14: Rua Faro, 80 | F14: Jardim Botânico | G14: 140 | H14: 2 anos | I14: 9 | K14: 18 | M14: 42 | N14: 1 | O14: 33 | P14: 1 | Q14: =SUM(I14,K14,M14,O14) -> 102 | R14: =SUM(J14,L14,N14,P14) -> 2 | S14: =IF((J14+L14)>=1,2,0) -> 0 | T14: =IF((N14+P14)>=1,2,0) -> 2 | U14: =SUM(G14-Q14-((S14*1)+(T14*1))) -> 36 | V14: =IF(U14<0,U14,0) -> 0
B15: 6 | C15: Centro Comunitário Alegria Das Crianças | D15: Centro Comunitário Alegria Das Crianças | E15: Rua Dois, 431 | F15: Rocinha | G15: 72 | H15: 2 anos | M15: 32 | O15: 40 | Q15: =SUM(I15,K15,M15,O15) -> 72 | R15: =SUM(J15,L15,N15,P15) -> 0 | S15: =IF((J15+L15)>=1,2,0) -> 0 | T15: =IF((N15+P15)>=1,2,0) -> 0 | U15: =SUM(G15-Q15-((S15*1)+(T15*1))) -> 0 | V15: =IF(U15<0,U15,0) -> 0
B16: 7 | C16: Centro Comunitário Da Rua Um – União Faz A Força | D16: Centro Comunitário Da Rua Um – União Faz A Força | E16: Estr. Da Gávea, 259 - Parte | F16: Rocinha | G16: 140 | H16: 1 ano | I16: 9 | K16: 15 | M16: 46 | O16: 77 | Q16: =SUM(I16,K16,M16,O16) -> 147 | R16: =SUM(J16,L16,N16,P16) -> 0 | S16: =IF((J16+L16)>=1,2,0) -> 0 | T16: =IF((N16+P16)>=1,2,0) -> 0 | U16: =SUM(G16-Q16-((S16*1)+(T16*1))) -> -7 | V16: =IF(U16<0,U16,0) -> -7
B17: 8 | C17: Centro De Educação Infantil Cristo Redentor | D17: Associação Palotina | E17: Rua Indiana, 59 | F17: Cosme Velho | G17: 65 | H17: 2 anos | M17: 30 | O17: 32 | Q17: =SUM(I17,K17,M17,O17) -> 62 | R17: =SUM(J17,L17,N17,P17) -> 0 | S17: =IF((J17+L17)>=1,2,0) -> 0 | T17: =IF((N17+P17)>=1,2,0) -> 0 | U17: =SUM(G17-Q17-((S17*1)+(T17*1))) -> 3 | V17: =IF(U17<0,U17,0) -> 0
B18: 9 | C18: Centro Educacional Esperança | D18: Primeira Igreja Batista Do Alto Da Boa Vista | E18: Estrada Do Biguá, 336 | F18: Alto Da Boa Vista | G18: 60 | H18: 2 anos | M18: 26 | O18: 34 | Q18: =SUM(I18,K18,M18,O18) -> 60 | R18: =SUM(J18,L18,N18,P18) -> 0 | S18: =IF((J18+L18)>=1,2,0) -> 0 | T18: =IF((N18+P18)>=1,2,0) -> 0 | U18: =SUM(G18-Q18-((S18*1)+(T18*1))) -> 0 | V18: =IF(U18<0,U18,0) -> 0
B19: 10 | C19: Centro Social Da Mulher Uêga | D19: Centro Social Da Mulher Uêga | E19: Rua Esperança, 37 – 2º Andar | F19: Rocinha | G19: 100 | H19: 2 anos | M19: 41 | O19: 49 | Q19: =SUM(I19,K19,M19,O19) -> 90 | R19: =SUM(J19,L19,N19,P19) -> 0 | S19: =IF((J19+L19)>=1,2,0) -> 0 | T19: =IF((N19+P19)>=1,2,0) -> 0 | U19: =SUM(G19-Q19-((S19*1)+(T19*1))) -> 10 | V19: =IF(U19<0,U19,0) -> 0
B20: 11 | C20: Centro Social E Aí Como É Que Fica? | D20: Centro Social E Aí Como É Que Fica? | E20: Estr. Da Gávea, 229 – Casa 1 | F20: Rocinha | G20: 65 | H20: 0 ano | I20: 10 | K20: 12 | M20: 22 | O20: 21 | Q20: =SUM(I20,K20,M20,O20) -> 65 | R20: =SUM(J20,L20,N20,P20) -> 0 | S20: =IF((J20+L20)>=1,2,0) -> 0 | T20: =IF((N20+P20)>=1,2,0) -> 0 | U20: =SUM(G20-Q20-((S20*1)+(T20*1))) -> 0 | V20: =IF(U20<0,U20,0) -> 0
B21: 12 | C21: Creche Berçário Maria Helena Da Rocinha | D21: Grupo Comunitário Creche Berçário Nova Jerusalém | E21: Trav. Esperança, 12 | F21: Rocinha | G21: 75 | H21: 1 ano | I21: 6 | K21: 21 | M21: 23 | O21: 25 | Q21: =SUM(I21,K21,M21,O21) -> 75 | R21: =SUM(J21,L21,N21,P21) -> 0 | S21: =IF((J21+L21)>=1,2,0) -> 0 | T21: =IF((N21+P21)>=1,2,0) -> 0 | U21: =SUM(G21-Q21-((S21*1)+(T21*1))) -> 0 | V21: =IF(U21<0,U21,0) -> 0
B22: 13 | C22: Creche Bezerra De Menezes | D22: Centro Espírita Cristófilos | E22: Rua Martins Ferreira, 57 | F22: Botafogo | G22: 50 | H22: 6 meses | I22: 3 | K22: 8 | M22: 16 | O22: 20 | Q22: =SUM(I22,K22,M22,O22) -> 47 | R22: =SUM(J22,L22,N22,P22) -> 0 | S22: =IF((J22+L22)>=1,2,0) -> 0 | T22: =IF((N22+P22)>=1,2,0) -> 0 | U22: =SUM(G22-Q22-((S22*1)+(T22*1))) -> 3 | V22: =IF(U22<0,U22,0) -> 0
B23: 14 | C23: Creche Casa Do Pobre De Nossa Senhora De Copacabana | D23: Creche Casa Do Pobre De Nossa Senhora De Copacabana | E23: Rua Hilário De Gouvea, 36 - 4º Andar | F23: Copacabana | G23: 79 | H23: 2 anos | M23: 40 | O23: 41 | Q23: =SUM(I23,K23,M23,O23) -> 81 | R23: =SUM(J23,L23,N23,P23) -> 0 | S23: =IF((J23+L23)>=1,2,0) -> 0 | T23: =IF((N23+P23)>=1,2,0) -> 0 | U23: =SUM(G23-Q23-((S23*1)+(T23*1))) -> -2 | V23: =IF(U23<0,U23,0) -> -2
B24: 15 | C24: Creche Casa Santa Marta | D24: Associação Dos Antigos Alunos Dos Padres Jesuítas (Asia) | E24: Rua Marechal Francisco De Moura, 234 | F24: Botafogo | G24: 96 | H24: 6 meses | I24: 18 | K24: 36 | M24: 20 | O24: 20 | Q24: =SUM(I24,K24,M24,O24) -> 94 | R24: =SUM(J24,L24,N24,P24) -> 0 | S24: =IF((J24+L24)>=1,2,0) -> 0 | T24: =IF((N24+P24)>=1,2,0) -> 0 | U24: =SUM(G24-Q24-((S24*1)+(T24*1))) -> 2 | V24: =IF(U24<0,U24,0) -> 0
B25: 16 | C25: Creche Chácara Do Céu | D25: Ação Comunitária Pró-Favela Dr. Marcello Cândia | E25: Estr. Da Independência, 161 | F25: Borel | G25: 60 | H25: 6 meses | K25: 15 | M25: 22 | O25: 23 | P25: 1 | Q25: =SUM(I25,K25,M25,O25) -> 60 | R25: =SUM(J25,L25,N25,P25) -> 1 | S25: =IF((J25+L25)>=1,2,0) -> 0 | T25: =IF((N25+P25)>=1,2,0) -> 2 | U25: =SUM(G25-Q25-((S25*1)+(T25*1))) -> -2 | V25: =IF(U25<0,U25,0) -> -2
B26: 17 | C26: Creche Chapeuzinho Marrom | D26: Mitra Arquiepiscopal Do Rio De Janeiro | E26: Rua Joaquim Pizarro, 63 | F26: Turano/Rio Comprido | G26: 42 | H26: 2 anos | M26: 17 | O26: 25 | Q26: =SUM(I26,K26,M26,O26) -> 42 | R26: =SUM(J26,L26,N26,P26) -> 0 | S26: =IF((J26+L26)>=1,2,0) -> 0 | T26: =IF((N26+P26)>=1,2,0) -> 0 | U26: =SUM(G26-Q26-((S26*1)+(T26*1))) -> 0 | V26: =IF(U26<0,U26,0) -> 0
B27: 18 | C27: Creche Comunitária Cantinho Da Natureza | D27: Obra Social Da Paróquia Santa Cruz De Copacabana | E27: Rua Euclides Da Rocha, 370 | F27: Copacabana | G27: 150 | H27: 6 meses | I27: 19 | K27: 39 | M27: 46 | N27: 2 | O27: 39 | P27: 1 | Q27: =SUM(I27,K27,M27,O27) -> 143 | R27: =SUM(J27,L27,N27,P27) -> 3 | S27: =IF((J27+L27)>=1,2,0) -> 0 | T27: =IF((N27+P27)>=1,2,0) -> 2 | U27: =SUM(G27-Q27-((S27*1)+(T27*1))) -> 5 | V27: =IF(U27<0,U27,0) -> 0
B28: 19 | C28: Creche Escadinha Do Saber | D28: Associação De Moradores Do Tijuaçu - Amoti | E28: Estr. Do Tijuaçu, 32 | F28: Alto Da Boa Vista | G28: 45 | H28: 2 anos | M28: 15 | N28: 1 | O28: 13 | P28: 1 | Q28: =SUM(I28,K28,M28,O28) -> 28 | R28: =SUM(J28,L28,N28,P28) -> 2 | S28: =IF((J28+L28)>=1,2,0) -> 0 | T28: =IF((N28+P28)>=1,2,0) -> 2 | U28: =SUM(G28-Q28-((S28*1)+(T28*1))) -> 15 | V28: =IF(U28<0,U28,0) -> 0
B29: 20 | C29: Creche Escola Meninos De Luz | D29: Lar Paulo De Tarso | E29: Rua Saint Romain, 142 | F29: Copacabana | G29: 88 | H29: 0 ano | I29: 12 | K29: 32 | M29: 22 | O29: 22 | P29: 1 | Q29: =SUM(I29,K29,M29,O29) -> 88 | R29: =SUM(J29,L29,N29,P29) -> 1 | S29: =IF((J29+L29)>=1,2,0) -> 0 | T29: =IF((N29+P29)>=1,2,0) -> 2 | U29: =SUM(G29-Q29-((S29*1)+(T29*1))) -> -2 | V29: =IF(U29<0,U29,0) -> -2
B30: 21 | C30: Creche Espaço Semente | D30: Jovens Com Uma Missão – Jocum Borel | E30: Travessa São Luiz, 99 | F30: Borel/Tijuca | G30: 80 | H30: 2 anos | M30: 37 | O30: 43 | Q30: =SUM(I30,K30,M30,O30) -> 80 | R30: =SUM(J30,L30,N30,P30) -> 0 | S30: =IF((J30+L30)>=1,2,0) -> 0 | T30: =IF((N30+P30)>=1,2,0) -> 0 | U30: =SUM(G30-Q30-((S30*1)+(T30*1))) -> 0 | V30: =IF(U30<0,U30,0) -> 0
B31: 22 | C31: Creche Esperança | D31: Sasp – Serviço De Assistência Social Pentecostal | E31: Rua Adalberto Ferreira, 35 | F31: Leblon | G31: 100 | H31: 6 meses | I31: 12 | J31: 1 | K31: 30 | M31: 28 | N31: 2 | O31: 33 | P31: 1 | Q31: =SUM(I31,K31,M31,O31) -> 103 | R31: =SUM(J31,L31,N31,P31) -> 4 | S31: =IF((J31+L31)>=1,2,0) -> 2 | T31: =IF((N31+P31)>=1,2,0) -> 2 | U31: =SUM(G31-Q31-((S31*1)+(T31*1))) -> -7 | V31: =IF(U31<0,U31,0) -> -7
B32: 23 | C32: Creche Maria Maria | D32: Grupo Comunitário Maria Maria Da Rocinha | E32: Estr. Da Gávea, 259, R. Um Casa 52 | F32: Rocinha | G32: 72 | H32: 6 meses | I32: 8 | K32: 18 | M32: 23 | O32: 23 | Q32: =SUM(I32,K32,M32,O32) -> 72 | R32: =SUM(J32,L32,N32,P32) -> 0 | S32: =IF((J32+L32)>=1,2,0) -> 0 | T32: =IF((N32+P32)>=1,2,0) -> 0 | U32: =SUM(G32-Q32-((S32*1)+(T32*1))) -> 0 | V32: =IF(U32<0,U32,0) -> 0
B33: 24 | C33: Creche Monsenhor Franca | D33: Instituto Missionário Comunhão E Participação | E33: Rua Tavares Bastos, 296 | F33: Catete | G33: 50 | H33: 2 anos | M33: 25 | O33: 25 | Q33: =SUM(I33,K33,M33,O33) -> 50 | R33: =SUM(J33,L33,N33,P33) -> 0 | S33: =IF((J33+L33)>=1,2,0) -> 0 | T33: =IF((N33+P33)>=1,2,0) -> 0 | U33: =SUM(G33-Q33-((S33*1)+(T33*1))) -> 0 | V33: =IF(U33<0,U33,0) -> 0
B34: 25 | C34: Creche Patinho Feliz | D34: Inatos – Instituto Nacional De Assis. Trabalho, Oportunidades E Saúde | E34: Rua Armando De Albuquerque, 168 | F34: Vila Isabel | G34: 170 | H34: 1 ano | K34: 58 | M34: 63 | N34: 1 | O34: 49 | P34: 1 | Q34: =SUM(I34,K34,M34,O34) -> 170 | R34: =SUM(J34,L34,N34,P34) -> 2 | S34: =IF((J34+L34)>=1,2,0) -> 0 | T34: =IF((N34+P34)>=1,2,0) -> 2 | U34: =SUM(G34-Q34-((S34*1)+(T34*1))) -> -2 | V34: =IF(U34<0,U34,0) -> -2
B35: 26 | C35: Creche Pré-Escola Comunitária Do 199 Pingo De Gente | D35: Creche Pré-Escola Comunitária Do 199 Pingo De Gente | E35: Estr. Da Gávea, 199-Beco 1/5/65 Casa 34 | F35: Rocinha | G35: 50 | H35: 2 anos | M35: 15 | O35: 35 | Q35: =SUM(I35,K35,M35,O35) -> 50 | R35: =SUM(J35,L35,N35,P35) -> 0 | S35: =IF((J35+L35)>=1,2,0) -> 0 | T35: =IF((N35+P35)>=1,2,0) -> 0 | U35: =SUM(G35-Q35-((S35*1)+(T35*1))) -> 0 | V35: =IF(U35<0,U35,0) -> 0
B36: 27 | C36: Creche Pré-Escola Comunitária Dois Irmãos | D36: Creche Pré-Escola Comunitária Dois Irmãos | E36: Est. Da Gávea, 325 – Beco 1-Casa 30 | F36: Rocinha | G36: 75 | H36: 1 ano | K36: 17 | M36: 24 | O36: 32 | Q36: =SUM(I36,K36,M36,O36) -> 73 | R36: =SUM(J36,L36,N36,P36) -> 0 | S36: =IF((J36+L36)>=1,2,0) -> 0 | T36: =IF((N36+P36)>=1,2,0) -> 0 | U36: =SUM(G36-Q36-((S36*1)+(T36*1))) -> 2 | V36: =IF(U36<0,U36,0) -> 0
B37: 28 | C37: Creche Sant’Anna | D37: Obra Social Cristo Redentor | E37: Rua Professor Luiz Cantanhede, 25 | F37: Laranjeiras | G37: 72 | H37: 2 anos | M37: 24 | O37: 48 | P37: 1 | Q37: =SUM(I37,K37,M37,O37) -> 72 | R37: =SUM(J37,L37,N37,P37) -> 1 | S37: =IF((J37+L37)>=1,2,0) -> 0 | T37: =IF((N37+P37)>=1,2,0) -> 2 | U37: =SUM(G37-Q37-((S37*1)+(T37*1))) -> -2 | V37: =IF(U37<0,U37,0) -> -2
B38: 29 | C38: Creche Santa Clara | D38: Casa De São Francisco De Assis | E38: Rua Alice, 308 | F38: Laranjeiras | G38: 40 | H38: 2 anos | M38: 19 | N38: 1 | O38: 19 | P38: 1 | Q38: =SUM(I38,K38,M38,O38) -> 38 | R38: =SUM(J38,L38,N38,P38) -> 2 | S38: =IF((J38+L38)>=1,2,0) -> 0 | T38: =IF((N38+P38)>=1,2,0) -> 2 | U38: =SUM(G38-Q38-((S38*1)+(T38*1))) -> 0 | V38: =IF(U38<0,U38,0) -> 0
B39: 30 | C39: Creche Santa Clara De Assis Na Providência De Deus | D39: Instituto Missionário Comunhão E Participação | E39: Rua Benedito Calixto, 92/94 | F39: Vidigal | G39: 71 | H39: 1 ano | K39: 11 | M39: 36 | N39: 2 | O39: 24 | Q39: =SUM(I39,K39,M39,O39) -> 71 | R39: =SUM(J39,L39,N39,P39) -> 2 | S39: =IF((J39+L39)>=1,2,0) -> 0 | T39: =IF((N39+P39)>=1,2,0) -> 2 | U39: =SUM(G39-Q39-((S39*1)+(T39*1))) -> -2 | V39: =IF(U39<0,U39,0) -> -2
B40: 31 | C40: Creche Santa Mônica | D40: Ação Comunitária Pró-Favela Dr. Marcello Cândia | E40: Estr. Da Independência, 56 | F40: Borel / Tijuca | G40: 140 | H40: 6 meses | I40: 12 | K40: 45 | M40: 44 | N40: 1 | O40: 38 | P40: 1 | Q40: =SUM(I40,K40,M40,O40) -> 139 | R40: =SUM(J40,L40,N40,P40) -> 2 | S40: =IF((J40+L40)>=1,2,0) -> 0 | T40: =IF((N40+P40)>=1,2,0) -> 2 | U40: =SUM(G40-Q40-((S40*1)+(T40*1))) -> -1 | V40: =IF(U40<0,U40,0) -> -1
B41: 32 | C41: Creche São Cosme E São Damião | D41: Mitra Arquiepiscopal Do Rio De Janeiro | E41: Rua Leopoldo, 434 | F41: Andaraí | G41: 86 | H41: 2 anos | M41: 36 | N41: 3 | O41: 44 | P41: 1 | Q41: =SUM(I41,K41,M41,O41) -> 80 | R41: =SUM(J41,L41,N41,P41) -> 4 | S41: =IF((J41+L41)>=1,2,0) -> 0 | T41: =IF((N41+P41)>=1,2,0) -> 2 | U41: =SUM(G41-Q41-((S41*1)+(T41*1))) -> 4 | V41: =IF(U41<0,U41,0) -> 0
B42: 33 | C42: CREI – Centro De Recuperação Infantil | D42: Crei – Centro De Recuperação Infantil | E42: Rua Joana Angélica, 203 | F42: Ipanema | G42: 50 | H42: 2 anos | M42: 10 | N42: 1 | O42: 37 | P42: 3 | Q42: =SUM(I42,K42,M42,O42) -> 47 | R42: =SUM(J42,L42,N42,P42) -> 4 | S42: =IF((J42+L42)>=1,2,0) -> 0 | T42: =IF((N42+P42)>=1,2,0) -> 2 | U42: =SUM(G42-Q42-((S42*1)+(T42*1))) -> 1 | V42: =IF(U42<0,U42,0) -> 0
...

Sheet QUADRO RESUMO
A1: ALUNOS MATRICULADOS
A2: CRE | B2: BI | C2: BII | D2: MI | E2: MII | F2: TOTAL CRE
A3: 1ª | B3: =SUM(MAIO!I4:I8) -> 0 | C3: =SUM(MAIO!K4:K8) -> 44 | D3: =SUM(MAIO!M4:M8) -> 127 | E3: =SUM(MAIO!O4:O8) -> 117 | F3: =SUM(B3:E3) -> 288
A4: 2ª | B4: =SUM(MAIO!I10:I58) -> 243 | C4: =SUM(MAIO!K10:K58) -> 731 | D4: =SUM(MAIO!M10:M58) -> 1477 | E4: =SUM(MAIO!O10:O58) -> 1632 | F4: =SUM(B4:E4) -> 4083
A5: 3ª | B5: =SUM(MAIO!I60:I94) -> 41 | C5: =SUM(MAIO!K60:K94) -> 783 | D5: =SUM(MAIO!M60:M94) -> 1732 | E5: =SUM(MAIO!O60:O94) -> 1766 | F5: =SUM(B5:E5) -> 4322
A6: 4ª | B6: =SUM(MAIO!I96:I135) -> 16 | C6: =SUM(MAIO!K96:K135) -> 1243 | D6: =SUM(MAIO!M96:M135) -> 2184 | E6: =SUM(MAIO!O96:O135) -> 1983 | F6: =SUM(B6:E6) -> 5426
A7: 5ª | B7: =SUM(MAIO!I137:I148) -> 7 | C7: =SUM(MAIO!K137:K148) -> 204 | D7: =SUM(MAIO!M137:M148) -> 585 | E7: =SUM(MAIO!O137:O148) -> 480 | F7: =SUM(B7:E7) -> 1276
A8: 6ª | B8: =SUM(MAIO!I150:I160) -> 15 | C8: =SUM(MAIO!K150:K160) -> 209 | D8: =SUM(MAIO!M150:M160) -> 563 | E8: =SUM(MAIO!O150:O160) -> 604 | F8: =SUM(B8:E8) -> 1391
A9: 7ª | B9: =SUM(MAIO!I162:I180) -> 46 | C9: =SUM(MAIO!K162:K180) -> 213 | D9: =SUM(MAIO!M162:M180) -> 1001 | E9: =SUM(MAIO!O162:O180) -> 1120 | F9: =SUM(B9:E9) -> 2380
A10: 8ª | B10: =SUM(MAIO!I182:I200) -> 43 | C10: =SUM(MAIO!K182:K200) -> 525 | D10: =SUM(MAIO!M182:M200) -> 882 | E10: =SUM(MAIO!O182:O200) -> 776 | F10: =SUM(B10:E10) -> 2226
A11: 9ª | B11: =SUM(MAIO!I202:I216) -> 0 | C11: =SUM(MAIO!K202:K216) -> 306 | D11: =SUM(MAIO!M202:M216) -> 518 | E11: =SUM(MAIO!O202:O216) -> 513 | F11: =SUM(B11:E11) -> 1337
A12: 10ª | B12: =SUM(MAIO!I218:I276) -> 77 | C12: =SUM(MAIO!K218:K276) -> 2014 | D12: =SUM(MAIO!M218:M276) -> 3421 | E12: =SUM(MAIO!O218:O276) -> 3269 | F12: =SUM(B12:E12) -> 8781
A13: 11ª | B13: =SUM(MAIO!I278:I283) -> 0 | C13: =SUM(MAIO!K278:K283) -> 189 | D13: =SUM(MAIO!M278:M283) -> 316 | E13: =SUM(MAIO!O278:O283) -> 336 | F13: =SUM(B13:E13) -> 841
A14: SUBTOTAL REDE | B14: =SUM(B3:B13) -> 488 | C14: =SUM(C3:C13) -> 6461 | D14: =SUM(D3:D13) -> 12806 | E14: =SUM(E3:E13) -> 12596
A15: TOTAL REDE | B15: =SUM(B3:E13) -> 32351
A17: CRE | B17: Nº DE UNIDADES | C17: META
A18: 1ª | B18: =COUNTA(MAIO!C4:C8) -> 5 | C18: 312
A19: 2ª | B19: 49 | C19: 4211
A20: 3ª | B20: 35 | C20: 4445
A21: 4ª | B21: 40 | C21: 6173
A22: 5ª | B22: 12 | C22: 1458
A23: 6ª | B23: 11 | C23: 1437
A24: 7ª | B24: 19 | C24: 2413
A25: 8ª | B25: 19 | C25: 2502
A26: 9ª | B26: 15 | C26: 1608
A27: 10ª | B27: 59 | C27: 9069
A28: 11ª | B28: 6 | C28: 842
A29: TOTAL REDE | B29: =SUM(B18:B28) -> 270 | C29: 34470
