Workbook

Sheet Apoio
A1: 1 | B1: 1
A2: 2 | B2: 1
A3: 3 | B3: 1
A4: 4 | B4: 1
A5: 5 | B5: 1
A6: 6 | B6: 1
A7: 7 | B7: 1
A8: 8 | B8: 1
A9: 9 | B9: 1
A10: 10 | B10: 1
A11: 11 | B11: 1
A12: 12 | B12: 1
... A250: 250 | B250: 10

Sheet Endereços
A1: DESIGNAÇÃO | B1: NOME DA CRECHE | C1: ENDEREÇO | D1: BAIRRO
A2: 1004 | B2: CP CRECHE CANTINHO FELIZ DE SANTA TERESA | C2: RUA ALMIRANTE ALEXANDRINA, 2495 | D2: SANTA TERESA
A3: 1005 | B3: CP CASA MATERNAL CORAÇÃO DE MÃE | C3: RUA CONCEIÇÃO, Nº 01 - COMPLEXO DO TURANO | D3: RIO COMPRIDO
A4: 1006 | B4: CP CRECHE DO TUIUTI | C4: RUA SÃO LUIZ GONZAGA, Nº 1612-FUNDOS | D4: BENFICA
A5: 1007 | B5: CP EDUCANDÁRIO NOSSA SENHORA DE NAZARÉ | C5: RUA DOUTOR AGRA, Nº 115 | D5: CATUMBI
A6: 1009 | B6: CP CRECHE COMUNITÁRIA ANITA WAY | C6: RUA DA AMÉRICA, 81 | D6: SANTO CRISTO
A7: 1010 | B7: CP CENTRO CULTURAL MONTESSORI - SÃO CRISTÓVÃO | C7: R. SÃO LUIZ GONZAGA, 1720 | D7: SÃO CRISTÓVÃO
A8: 2001 | B8: CP CRECHE ESPAÇO SEMENTE | C8: TRAVESSA SÃO LUIZ, 99 | D8: BOREL / TIJUCA
A9: 2002 | B9: CP EDUCANDÁRIO CASA DE JACIRA | C9: RUA AGUIAR, 72 | D9: TIJUCA
A10: 2003 | B10: CP CENTRO COMUNITÁRIO DA RUA UM UNIÃO FAZ A FORÇA | C10: ESTR. DA GÁVEA, 259 - PARTE | D10: ROCINHA
A11: 2004 | B11: CP AÇÃO SOCIAL PADRE ANCHIETA - ASPA | C11: TRAVESSA LUZ, 13 | D11: ROCINHA
A12: 2005 | B12: CP ESCOLA COMUNITÁRIA DO CANTAGALO | C12: RUA SAINT ROMAIN, 200/RUA CÂNDIDO PORTINARI, 05 | D12: COPACABANA
A13: 2006 | B13: CP CRECHE PRÉ-ESCOLA COMUNITÁRIA DOIS IRMÃOS | C13: EST. DA GÁVEA, 325 - BECO 1-CASA 30 | D13: ROCINHA
... A195: 7035 | B195: CP AEMMAC - ANIL | C195: AV. TENENTE CORONEL MUNIZ DE ARAGÃO, 219 | D195: JACAREPAGUÁ
A196: 7036 | B196: CAAD UNIVERSO ENCANTADO | C196: 0 | D196: JACAREPAGUÁ
A197: 7037 | B197: CAAD- UNIVERSO DA CRIANÇA | C197: 0 | D197: JACAREPAGUÁ
A198: 7038 | B198: CAAD - UNIVERSO DAS FLORES | C198: 0 | D198: VILA VALQUEIRE
A199: 7039 | B199: JARDIM CLARICE | C199: 0 | D199: JACAREPAGUÁ
A200: 7040 | B200: VALE DO SOL PRAÇA SECA | C200: 0 | D200: JACAREPAGUÁ
A201: 7041 | B201: VALE DO SOL TAQUARA | C201: 0 | D201: TAQUARA / JACAREPAGUÁ
A202: 7042 | B202: INSTITUTO EDUCACIONAL DIVA ALVES - Unidade II | C202: 0 | D202: JACAREPAGUÁ
A203: 7043 | B203: ESPAÇO DE EDUCAÇÃO INFANTIL PEQUENO APRENDIZ | C203: Estrada dos Bandeirantes, 11227 - Via A - s/nº | D203: VARGEM PEQUENA
A204: 7044 | B204: CRECHE COMUNITÁRIA AMOR DE MÃE | C204: Av. Genaro de Carvalho 3735 | D204: RECREIO DOS BANDEIRANTES
A205: 7045 | B205: JARDIM ESCOLA TURMINHA DA ARCA | C205: Av. Isabel Domingues, 20 | D205: GARDÊNIA AZUL
A206: 7046 | B206: ASSOCIAÇÃO CRECHE ESCOLA SILVINA VIRGÍNIA | C206: Rua Frederico Quartarolli, 394 | D206: RECREIO DOS BANDEIRANTES
A207: 8002 | B207: CP CRECHE ESPÍRITA FRANCISCO DE ASSIS | C207: ESTR. DO ENGENHO NOVO, 235 | D207: REALENGO
A208: 8003 | B208: CP CRECHE CRIANÇA JABOUR | C208: RUA CROÁCIA, 05 C. 16 | D208: JABOUR
A209: 8004 | B209: CP CRECHE COMUNITÁRIA NINO | C209: RUA FORT LAMY, S/Nº, LOTE 01, QUADRA 32 | D209: VILA KENNEDY
A210: 8005 | B210: CP CRECHE E ESCOLA COMUNITÁRIA GENTE INOCENTE - REALENGO | C210: ESTR. DA ÁGUA BRANCA, 4090 | D210: REALENGO
A211: 8006 | B211: CP FUNDAÇÃO CASA DA JOANINHA - CRECHE | C211: ESTR. DA ÁGUA BRANCA, 640 | D211: MAGALHÃES BASTOS
A212: 8007 | B212: CP CRECHE E ESCOLA COMUNITÁRIA GENTE INOCENTE - BANGU | C212: ESTR. DA ÁGUA BRANCA, 4296 | D212: BANGU
A213: 8008 | B213: CP ASSOCIAÇÃO DE MORADORES DO CONJUNTO PEDRO I E ADJACÊNCIAS | C213: RUA CÍTARA, 138 | D213: REALENGO
A214: 8009 | B214: CP ASSOCIAÇÃO RECREATIVA PINGUINHO DE GENTE | C214: RUA DR. AUGUSTO FIGUEIREDO, 2002 | D214: SENADOR CAMARÁ
... A351: 11010 | B351: CHALÉ SEMENTINHA (ILHA DO GOVERNADOR) | C351: Rua Engenheiro Rozauro Zambrano, 234, Jardim Guanabara | D351: JARDIM GUANABARA

Sheet Maio-2024
A1: Realidade: X
A2: Fonte: Anexo XIV
N3: BERÇÁRIO I | S3: BERÇÁRIO II | X3: MATERNAL I | AC3: MATERNAL II
A4: CRE | B4: Nº | C4: CÓDIGO SGA | D4: INEP | E4: CNPJ | F4: SISEP | G4: Denominação SGA | H4: Creche Parceira | I4: Mantenedora | J4: Endereço | K4: Bairro | L4: Meta | M4: Faixa Etária | N4: Turma | O4: Aluno | P4: Incluído | Q4: Abatimento Vagas | R4: Turma Mista? | S4: Turma | T4: Aluno | U4: Incluído | V4: Abatimento Vagas | W4: Turma Mista? | X4: Turma | Y4: Aluno | Z4: Incluído | AA4: Abatimento Vagas | AB4: Turma Mista? | AC4: Turma | AD4: Aluno | AE4: Incluído | AF4: Abatimento Vagas | AG4: Turma Mista? | AH4: Total Alunos | AI4: Total Incluídos | AJ4: Abatimentos | AK4: Vagas | AL4: Excedentes | AM4: Obs | AN4: Realidade Março | AO4: Diferença | AP4: Verificação Aluno/Meta
A5: 1 | B5: 1 | C5: 1004 | D5: 33122261 | E5: 02287214000116 | F5: 010055 | G5: CP CRECHE CANTINHO FELIZ DE SANTA TERESA | H5: CRECHE CANTINHO FELIZ DE SANTA TERESA | I5: INSTITUTO TRILHO | J5: RUA ALMIRANTE ALEXANDRINA, 2495 | K5: SANTA TERESA | L5: 50 | N5: =IFERROR(VLOOKUP(O5,Apoio!A:B,2,0),"") | O5: =IFERROR(VLOOKUP(C5,'[1]TB DIN'!$B:$D,3,0),"AGUARDANDO ANEXO") -> 0 | P5: =IFERROR(VLOOKUP(C5,'[1]TB DIN INCLUIDOS'!$B:$H,3,0),"AGUARDANDO ANEXO") -> 0 | Q5: {=_xlfn.IFS((P5>N5),(N5*2),(P5<=N5),(P5*2))} -> 0 | S5: =IFERROR(VLOOKUP(T5,Apoio!A:B,2,0),"") | T5: =IFERROR(VLOOKUP(C5,'[1]TB DIN'!$B:$H,4,0),"AGUARDANDO ANEXO") -> 0 | U5: =IFERROR(VLOOKUP(C5,'[1]TB DIN INCLUIDOS'!$B:$H,4,0),"AGUARDANDO ANEXO") -> 0 | V5: {=_xlfn.IFS((U5>S5),(S5*2),(U5<=S5),(U5*2))} -> 0 | X5: =IFERROR(VLOOKUP(Y5,Apoio!A:B,2,0),"") -> 2 | Y5: =IFERROR(VLOOKUP(C5,'[1]TB DIN'!$B:$H,5,0),"AGUARDANDO ANEXO") -> 26 | Z5: =IFERROR(VLOOKUP(C5,'[1]TB DIN INCLUIDOS'!$B:$H,5,0),"AGUARDANDO ANEXO") -> 0 | AA5: {=_xlfn.IFS((Z5>X5),(X5*2),(Z5<=X5),(Z5*2))} -> 0 | AC5: =IFERROR(VLOOKUP(AD5,Apoio!A:B,2,0),"") -> 1 | AD5: 24 | AE5: =IFERROR(VLOOKUP(C5,'[1]TB DIN INCLUIDOS'!$B:$H,6,0),"AGUARDANDO ANEXO") -> 0 | AF5: {=_xlfn.IFS((AE5>AC5),(AC5*2),(AE5<=AC5),(AE5*2))} -> 0 | AH5: =SUM(O5,T5,Y5,AD5) -> 50 | AI5: =SUM(P5,U5,Z5,AE5) -> 0 | AJ5: =SUM(Q5,V5,AA5,AF5) -> 0 | AK5: =IF(L5-AH5-Q5-V5-AA5-AF5>0,L5-AH5-Q5-V5-AA5-AF5,0) -> 0 | AL5: =IF(L5-O5-Q5-T5-V5-Y5-AA5-AD5-AF5<0,L5-O5-Q5-T5-V5-Y5-AA5-AD5-AF5,0) -> 0 | AM5: manutenção | AN5: =VLOOKUP(C5,'[2]MARÇO-2024'!$B:$M,12,0) -> 49 | AO5: =AN5-AH5 -> -1 | AP5: =IF(AH5>L5,"Qt de aluno maior que a meta","")
A6: 1 | B6: 2 | C6: 1005 | D6: 33184437 | E6: 68696962000160 | F6: 010134 | G6: CP CASA MATERNAL CORAÇÃO DE MÃE | H6: CASA MATERNAL CORAÇÃO DE MÃE | I6: INSTITUTO MISSIONÁRIO COMUNHÃO E PARTICIPAÇÃO | J6: RUA CONCEIÇÃO, Nº 01 - COMPLEXO DO TURANO | K6: RIO COMPRIDO | L6: 40 | N6: =IFERROR(VLOOKUP(O6,Apoio!A:B,2,0),"") | O6: =IFERROR(VLOOKUP(C6,'[1]TB DIN'!$B:$D,3,0),"AGUARDANDO ANEXO") -> 0 | P6: =IFERROR(VLOOKUP(C6,'[1]TB DIN INCLUIDOS'!$B:$H,3,0),"AGUARDANDO ANEXO") -> 0 | Q6: {=_xlfn.IFS((P6>N6),(N6*2),(P6<=N6),(P6*2))} -> 0 | S6: =IFERROR(VLOOKUP(T6,Apoio!A:B,2,0),"") | T6: =IFERROR(VLOOKUP(C6,'[1]TB DIN'!$B:$H,4,0),"AGUARDANDO ANEXO") -> 0 | U6: =IFERROR(VLOOKUP(C6,'[1]TB DIN INCLUIDOS'!$B:$H,4,0),"AGUARDANDO ANEXO") -> 0 | V6: {=_xlfn.IFS((U6>S6),(S6*2),(U6<=S6),(U6*2))} -> 0 | X6: =IFERROR(VLOOKUP(Y6,Apoio!A:B,2,0),"") -> 1 | Y6: =IFERROR(VLOOKUP(C6,'[1]TB DIN'!$B:$H,5,0),"AGUARDANDO ANEXO") -> 19 | Z6: =IFERROR(VLOOKUP(C6,'[1]TB DIN INCLUIDOS'!$B:$H,5,0),"AGUARDANDO ANEXO") -> 0 | AA6: {=_xlfn.IFS((Z6>X6),(X6*2),(Z6<=X6),(Z6*2))} -> 0 | AC6: =IFERROR(VLOOKUP(AD6,Apoio!A:B,2,0),"") -> 1 | AD6: 21 | AE6: =IFERROR(VLOOKUP(C6,'[1]TB DIN INCLUIDOS'!$B:$H,6,0),"AGUARDANDO ANEXO") -> 0 | AF6: {=_xlfn.IFS((AE6>AC6),(AC6*2),(AE6<=AC6),(AE6*2))} -> 0 | AH6: =SUM(O6,T6,Y6,AD6) -> 40 | AI6: =SUM(P6,U6,Z6,AE6) -> 0 | AJ6: =SUM(Q6,V6,AA6,AF6) -> 0 | AK6: =IF(L6-AH6-Q6-V6-AA6-AF6>0,L6-AH6-Q6-V6-AA6-AF6,0) -> 0 | AL6: =IF(L6-O6-Q6-T6-V6-Y6-AA6-AD6-AF6<0,L6-O6-Q6-T6-V6-Y6-AA6-AD6-AF6,0) -> 0 | AM6: manutenção | AN6: =VLOOKUP(C6,'[2]MARÇO-2024'!$B:$M,12,0) -> 40 | AO6: =AN6-AH6 -> 0 | AP6: =IF(AH6>L6,"Qt de aluno maior que a meta","")
A7: 1 | B7: 3 | C7: 1006 | D7: 33188564 | E7: 02717198000154 | F7: 010005 | G7: CP CRECHE DO TUIUTI | H7: CRECHE DO TUIUTI | I7: NÚCLEO DE AÇÃO COMUNITÁRIA E DESENVOLVIMENTO SOCIAL - NACODES | J7: RUA SÃO LUIZ GONZAGA, Nº 1612-FUNDOS | K7: BENFICA | L7: 147 | N7: =IFERROR(VLOOKUP(O7,Apoio!A:B,2,0),"") | O7: =IFERROR(VLOOKUP(C7,'[1]TB DIN'!$B:$D,3,0),"AGUARDANDO ANEXO") -> 0 | P7: =IFERROR(VLOOKUP(C7,'[1]TB DIN INCLUIDOS'!$B:$H,3,0),"AGUARDANDO ANEXO") -> 0 | Q7: {=_xlfn.IFS((P7>N7),(N7*2),(P7<=N7),(P7*2))} -> 0 | S7: =IFERROR(VLOOKUP(T7,Apoio!A:B,2,0),"") -> 2 | T7: 44 | U7: =IFERROR(VLOOKUP(C7,'[1]TB DIN INCLUIDOS'!$B:$H,4,0),"AGUARDANDO ANEXO") -> 0 | V7: {=_xlfn.IFS((U7>S7),(S7*2),(U7<=S7),(U7*2))} -> 0 | X7: =IFERROR(VLOOKUP(Y7,Apoio!A:B,2,0),"") -> 3 | Y7: 63 | Z7: =IFERROR(VLOOKUP(C7,'[1]TB DIN INCLUIDOS'!$B:$H,5,0),"AGUARDANDO ANEXO") -> 0 | AA7: {=_xlfn.IFS((Z7>X7),(X7*2),(Z7<=X7),(Z7*2))} -> 0 | AC7: =IFERROR(VLOOKUP(AD7,Apoio!A:B,2,0),"") -> 2 | AD7: =IFERROR(VLOOKUP(C7,'[1]TB DIN'!$B:$H,6,0),"AGUARDANDO ANEXO") -> 40 | AE7: =IFERROR(VLOOKUP(C7,'[1]TB DIN INCLUIDOS'!$B:$H,6,0),"AGUARDANDO ANEXO") -> 0 | AF7: {=_xlfn.IFS((AE7>AC7),(AC7*2),(AE7<=AC7),(AE7*2))} -> 0 | AH7: =SUM(O7,T7,Y7,AD7) -> 147 | AI7: =SUM(P7,U7,Z7,AE7) -> 0 | AJ7: =SUM(Q7,V7,AA7,AF7) -> 0 | AK7: =IF(L7-AH7-Q7-V7-AA7-AF7>0,L7-AH7-Q7-V7-AA7-AF7,0) -> 0 | AL7: =IF(L7-O7-Q7-T7-V7-Y7-AA7-AD7-AF7<0,L7-O7-Q7-T7-V7-Y7-AA7-AD7-AF7,0) -> 0 | AM7: manutenção | AN7: =VLOOKUP(C7,'[2]MARÇO-2024'!$B:$M,12,0) -> 147 | AO7: =AN7-AH7 -> 0 | AP7: =IF(AH7>L7,"Qt de aluno maior que a meta","")
A8: 1 | B8: 4 | C8: 1007 | D8: 33062978 | E8: 34100438000163 | F8: 010023 | G8: CP EDUCANDÁRIO NOSSA SENHORA DE NAZARÉ | H8: EDUCANDÁRIO NOSSA SENHORA DE NAZARÉ | I8: CONGREGAÇÃO DAS PEQUENAS IRMÃS DA DIVINA PROVIDÊNCIA | J8: RUA DOUTOR AGRA, Nº 115 | K8: CATUMBI | L8: 30 | N8: =IFERROR(VLOOKUP(O8,Apoio!A:B,2,0),"") | O8: =IFERROR(VLOOKUP(C8,'[1]TB DIN'!$B:$D,3,0),"AGUARDANDO ANEXO") -> 0 | P8: =IFERROR(VLOOKUP(C8,'[1]TB DIN INCLUIDOS'!$B:$H,3,0),"AGUARDANDO ANEXO") -> 0 | Q8: {=_xlfn.IFS((P8>N8),(N8*2),(P8<=N8),(P8*2))} -> 0 | S8: =IFERROR(VLOOKUP(T8,Apoio!A:B,2,0),"") | T8: =IFERROR(VLOOKUP(C8,'[1]TB DIN'!$B:$H,4,0),"AGUARDANDO ANEXO") -> 0 | U8: =IFERROR(VLOOKUP(C8,'[1]TB DIN INCLUIDOS'!$B:$H,4,0),"AGUARDANDO ANEXO") -> 0 | V8: {=_xlfn.IFS((U8>S8),(S8*2),(U8<=S8),(U8*2))} -> 0 | X8: =IFERROR(VLOOKUP(Y8,Apoio!A:B,2,0),"") -> 1 | Y8: =IFERROR(VLOOKUP(C8,'[1]TB DIN'!$B:$H,5,0),"AGUARDANDO ANEXO") -> 14 | Z8: =IFERROR(VLOOKUP(C8,'[1]TB DIN INCLUIDOS'!$B:$H,5,0),"AGUARDANDO ANEXO") -> 0 | AA8: {=_xlfn.IFS((Z8>X8),(X8*2),(Z8<=X8),(Z8*2))} -> 0 | AC8: =IFERROR(VLOOKUP(AD8,Apoio!A:B,2,0),"") -> 1 | AD8: =IFERROR(VLOOKUP(C8,'[1]TB DIN'!$B:$H,6,0),"AGUARDANDO ANEXO") -> 15 | AE8: =IFERROR(VLOOKUP(C8,'[1]TB DIN INCLUIDOS'!$B:$H,6,0),"AGUARDANDO ANEXO") -> 1 | AF8: {=_xlfn.IFS((AE8>AC8),(AC8*2),(AE8<=AC8),(AE8*2))} -> 2 | AH8: =SUM(O8,T8,Y8,AD8) -> 29 | AI8: =SUM(P8,U8,Z8,AE8) -> 1 | AJ8: =SUM(Q8,V8,AA8,AF8) -> 2 | AK8: =IF(L8-AH8-Q8-V8-AA8-AF8>0,L8-AH8-Q8-V8-AA8-AF8,0) -> 0 | AL8: =IF(L8-O8-Q8-T8-V8-Y8-AA8-AD8-AF8<0,L8-O8-Q8-T8-V8-Y8-AA8-AD8-AF8,0) -> -1 | AM8: manutenção | AN8: =VLOOKUP(C8,'[2]MARÇO-2024'!$B:$M,12,0) -> 29 | AO8: =AN8-AH8 -> 0 | AP8: =IF(AH8>L8,"Qt de aluno maior que a meta","")
A9: 1 | B9: 5 | C9: 1009 | D9: 33196141 | E9: 19701694000112 | F9: 010037 | G9: CP CRECHE COMUNITÁRIA ANITA WAY | H9: CRECHE COMUNITÁRIA ANITA WAY | I9: PROVIDENCIANDO A FAVOR DA VIDA | J9: RUA DA AMÉRICA, 81 | K9: SANTO CRISTO | L9: 130 | N9: =IFERROR(VLOOKUP(O9,Apoio!A:B,2,0),"") | O9: =IFERROR(VLOOKUP(C9,'[1]TB DIN'!$B:$D,3,0),"AGUARDANDO ANEXO") -> 0 | P9: =IFERROR(VLOOKUP(C9,'[1]TB DIN INCLUIDOS'!$B:$H,3,0),"AGUARDANDO ANEXO") -> 0 | Q9: {=_xlfn.IFS((P9>N9),(N9*2),(P9<=N9),(P9*2))} -> 0 | S9: =IFERROR(VLOOKUP(T9,Apoio!A:B,2,0),"") -> 1 | T9: 17 | U9: =IFERROR(VLOOKUP(C9,'[1]TB DIN INCLUIDOS'!$B:$H,4,0),"AGUARDANDO ANEXO") -> 0 | V9: {=_xlfn.IFS((U9>S9),(S9*2),(U9<=S9),(U9*2))} -> 0 | X9: =IFERROR(VLOOKUP(Y9,Apoio!A:B,2,0),"") -> 3 | Y9: 53 | Z9: =IFERROR(VLOOKUP(C9,'[1]TB DIN INCLUIDOS'!$B:$H,5,0),"AGUARDANDO ANEXO") -> 0 | AA9: {=_xlfn.IFS((Z9>X9),(X9*2),(Z9<=X9),(Z9*2))} -> 0 | AC9: =IFERROR(VLOOKUP(AD9,Apoio!A:B,2,0),"") -> 3 | AD9: 55 | AE9: =IFERROR(VLOOKUP(C9,'[1]TB DIN INCLUIDOS'!$B:$H,6,0),"AGUARDANDO ANEXO") -> 2 | AF9: {=_xlfn.IFS((AE9>AC9),(AC9*2),(AE9<=AC9),(AE9*2))} -> 4 | AH9: =SUM(O9,T9,Y9,AD9) -> 125 | AI9: =SUM(P9,U9,Z9,AE9) -> 2 | AJ9: =SUM(Q9,V9,AA9,AF9) -> 4 | AK9: =IF(L9-AH9-Q9-V9-AA9-AF9>0,L9-AH9-Q9-V9-AA9-AF9,0) -> 1 | AL9: =IF(L9-O9-Q9-T9-V9-Y9-AA9-AD9-AF9<0,L9-O9-Q9-T9-V9-Y9-AA9-AD9-AF9,0) -> 0 | AM9: manutenção | AN9: =VLOOKUP(C9,'[2]MARÇO-2024'!$B:$M,12,0) -> 128 | AO9: =AN9-AH9 -> 3 | AP9: =IF(AH9>L9,"Qt de aluno maior que a meta","")
A10: 1 | B10: 6 | C10: 1010 | D10: 33196311 | E10: 35455216000126 | F10: 010135 | G10: CP CENTRO CULTURAL MONTESSORI - SÃO CRISTÓVÃO | H10: CENTRO CULTURAL MONTESSORI (SÃO CRISTÓVÃO) | I10: CENTRO CULTURAL MONTESSORI | J10: R. SÃO LUIZ GONZAGA, 1720 | K10: SÃO CRISTÓVÃO | L10: 297 | N10: =IFERROR(VLOOKUP(O10,Apoio!A:B,2,0),"") | O10: =IFERROR(VLOOKUP(C10,'[1]TB DIN'!$B:$D,3,0),"AGUARDANDO ANEXO") -> 0 | P10: =IFERROR(VLOOKUP(C10,'[1]TB DIN INCLUIDOS'!$B:$H,3,0),"AGUARDANDO ANEXO") -> 0 | Q10: {=_xlfn.IFS((P10>N10),(N10*2),(P10<=N10),(P10*2))} -> 0 | S10: =IFERROR(VLOOKUP(T10,Apoio!A:B,2,0),"") -> 3 | T10: 75 | U10: =IFERROR(VLOOKUP(C10,'[1]TB DIN INCLUIDOS'!$B:$H,4,0),"AGUARDANDO ANEXO") -> 0 | V10: {=_xlfn.IFS((U10>S10),(S10*2),(U10<=S10),(U10*2))} -> 0 | X10: =IFERROR(VLOOKUP(Y10,Apoio!A:B,2,0),"") -> 5 | Y10: =IFERROR(VLOOKUP(C10,'[1]TB DIN'!$B:$H,5,0),"AGUARDANDO ANEXO") -> 116 | Z10: =IFERROR(VLOOKUP(C10,'[1]TB DIN INCLUIDOS'!$B:$H,5,0),"AGUARDANDO ANEXO") -> 0 | AA10: {=_xlfn.IFS((Z10>X10),(X10*2),(Z10<=X10),(Z10*2))} -> 0 | AC10: =IFERROR(VLOOKUP(AD10,Apoio!A:B,2,0),"") -> 5 | AD10: 102 | AE10: =IFERROR(VLOOKUP(C10,'[1]TB DIN INCLUIDOS'!$B:$H,6,0),"AGUARDANDO ANEXO") -> 2 | AF10: {=_xlfn.IFS((AE10>AC10),(AC10*2),(AE10<=AC10),(AE10*2))} -> 4 | AH10: =SUM(O10,T10,Y10,AD10) -> 293 | AI10: =SUM(P10,U10,Z10,AE10) -> 2 | AJ10: =SUM(Q10,V10,AA10,AF10) -> 4 | AK10: =IF(L10-AH10-Q10-V10-AA10-AF10>0,L10-AH10-Q10-V10-AA10-AF10,0) -> 0 | AL10: =IF(L10-O10-Q10-T10-V10-Y10-AA10-AD10-AF10<0,L10-O10-Q10-T10-V10-Y10-AA10-AD10-AF10,0) -> 0 | AM10: manutenção | AN10: =VLOOKUP(C10,'[2]MARÇO-2024'!$B:$M,12,0) -> 297 | AO10: =AN10-AH10 -> 4 | AP10: =IF(AH10>L10,"Qt de aluno maior que a meta","")
A11: 2 | B11: 1 | C11: 2001 | D11: 33172820 | E11: 17433591000193 | F11: 021365 | G11: CP CRECHE ESPAÇO SEMENTE | H11: CRECHE ESPAÇO SEMENTE | I11: JOVENS COM UMA MISSÃO - JOCUM BOREL | J11: TRAVESSA SÃO LUIZ, 99 | K11: BOREL / TIJUCA | L11: 80 | N11: =IFERROR(VLOOKUP(O11,Apoio!A:B,2,0),"") | O11: =IFERROR(VLOOKUP(C11,'[1]TB DIN'!$B:$D,3,0),"AGUARDANDO ANEXO") -> 0 | P11: =IFERROR(VLOOKUP(C11,'[1]TB DIN INCLUIDOS'!$B:$H,3,0),"AGUARDANDO ANEXO") -> 0 | Q11: {=_xlfn.IFS((P11>N11),(N11*2),(P11<=N11),(P11*2))} -> 0 | S11: =IFERROR(VLOOKUP(T11,Apoio!A:B,2,0),"") | T11: =IFERROR(VLOOKUP(C11,'[1]TB DIN'!$B:$H,4,0),"AGUARDANDO ANEXO") -> 0 | U11: =IFERROR(VLOOKUP(C11,'[1]TB DIN INCLUIDOS'!$B:$H,4,0),"AGUARDANDO ANEXO") -> 0 | V11: {=_xlfn.IFS((U11>S11),(S11*2),(U11<=S11),(U11*2))} -> 0 | X11: =IFERROR(VLOOKUP(Y11,Apoio!A:B,2,0),"") -> 2 | Y11: =IFERROR(VLOOKUP(C11,'[1]TB DIN'!$B:$H,5,0),"AGUARDANDO ANEXO") -> 38 | Z11: =IFERROR(VLOOKUP(C11,'[1]TB DIN INCLUIDOS'!$B:$H,5,0),"AGUARDANDO ANEXO") -> 1 | AA11: {=_xlfn.IFS((Z11>X11),(X11*2),(Z11<=X11),(Z11*2))} -> 2 | AC11: =IFERROR(VLOOKUP(AD11,Apoio!A:B,2,0),"") -> 2 | AD11: =IFERROR(VLOOKUP(C11,'[1]TB DIN'!$B:$H,6,0),"AGUARDANDO ANEXO") -> 41 | AE11: =IFERROR(VLOOKUP(C11,'[1]TB DIN INCLUIDOS'!$B:$H,6,0),"AGUARDANDO ANEXO") -> 0 | AF11: {=_xlfn.IFS((AE11>AC11),(AC11*2),(AE11<=AC11),(AE11*2))} -> 0 | AH11: =SUM(O11,T11,Y11,AD11) -> 79 | AI11: =SUM(P11,U11,Z11,AE11) -> 1 | AJ11: =SUM(Q11,V11,AA11,AF11) -> 2 | AK11: =IF(L11-AH11-Q11-V11-AA11-AF11>0,L11-AH11-Q11-V11-AA11-AF11,0) -> 0 | AL11: =IF(L11-O11-Q11-T11-V11-Y11-AA11-AD11-AF11<0,L11-O11-Q11-T11-V11-Y11-AA11-AD11-AF11,0) -> -1 | AM11: manutenção | AN11: =VLOOKUP(C11,'[2]MARÇO-2024'!$B:$M,12,0) -> 79 | AO11: =AN11-AH11 -> 0 | AP11: =IF(AH11>L11,"Qt de aluno maior que a meta","")
A12: 2 | B12: 2 | C12: 2002 | D12: 33066442 | E12: 33784406000161 | F12: 020240 | G12: CP EDUCANDÁRIO CASA DE JACIRA | H12: EDUCANDÁRIO CASA DE JACIRA | I12: CASA DE JACIRA AUXÍLIO À INFÂNCIA | J12: RUA AGUIAR, 72 | K12: TIJUCA | L12: 24 | N12: =IFERROR(VLOOKUP(O12,Apoio!A:B,2,0),"") | O12: =IFERROR(VLOOKUP(C12,'[1]TB DIN'!$B:$D,3,0),"AGUARDANDO ANEXO") -> 0 | P12: =IFERROR(VLOOKUP(C12,'[1]TB DIN INCLUIDOS'!$B:$H,3,0),"AGUARDANDO ANEXO") -> 0 | Q12: {=_xlfn.IFS((P12>N12),(N12*2),(P12<=N12),(P12*2))} -> 0 | S12: =IFERROR(VLOOKUP(T12,Apoio!A:B,2,0),"") | T12: =IFERROR(VLOOKUP(C12,'[1]TB DIN'!$B:$H,4,0),"AGUARDANDO ANEXO") -> 0 | U12: =IFERROR(VLOOKUP(C12,'[1]TB DIN INCLUIDOS'!$B:$H,4,0),"AGUARDANDO ANEXO") -> 0 | V12: {=_xlfn.IFS((U12>S12),(S12*2),(U12<=S12),(U12*2))} -> 0 | X12: =IFERROR(VLOOKUP(Y12,Apoio!A:B,2,0),"") | Y12: =IFERROR(VLOOKUP(C12,'[1]TB DIN'!$B:$H,5,0),"AGUARDANDO ANEXO") -> 0 | Z12: =IFERROR(VLOOKUP(C12,'[1]TB DIN INCLUIDOS'!$B:$H,5,0),"AGUARDANDO ANEXO") -> 0 | AA12: {=_xlfn.IFS((Z12>X12),(X12*2),(Z12<=X12),(Z12*2))} -> 0 | AC12: =IFERROR(VLOOKUP(AD12,Apoio!A:B,2,0),"") -> 1 | AD12: =IFERROR(VLOOKUP(C12,'[1]TB DIN'!$B:$H,6,0),"AGUARDANDO ANEXO") -> 24 | AE12: =IFERROR(VLOOKUP(C12,'[1]TB DIN INCLUIDOS'!$B:$H,6,0),"AGUARDANDO ANEXO") -> 0 | AF12: {=_xlfn.IFS((AE12>AC12),(AC12*2),(AE12<=AC12),(AE12*2))} -> 0 | AH12: =SUM(O12,T12,Y12,AD12) -> 24 | AI12: =SUM(P12,U12,Z12,AE12) -> 0 | AJ12: =SUM(Q12,V12,AA12,AF12) -> 0 | AK12: =IF(L12-AH12-Q12-V12-AA12-AF12>0,L12-AH12-Q12-V12-AA12-AF12,0) -> 0 | AL12: =IF(L12-O12-Q12-T12-V12-Y12-AA12-AD12-AF12<0,L12-O12-Q12-T12-V12-Y12-AA12-AD12-AF12,0) -> 0 | AM12: manutenção | AN12: =VLOOKUP(C12,'[2]MARÇO-2024'!$B:$M,12,0) -> 24 | AO12: =AN12-AH12 -> 0 | AP12: =IF(AH12>L12,"Qt de aluno maior que a meta","")
A13: 2 | B13: 3 | C13: 2003 | D13: 33095388 | E13: 27052182000109 | F13: 020480 | G13: CP CENTRO COMUNITÁRIO DA RUA UM UNIÃO FAZ A FORÇA | H13: CENTRO COMUNITÁRIO DA RUA UM - UNIÃO FAZ A FORÇA | I13: CENTRO COMUNITÁRIO DA RUA UM - UNIÃO FAZ A FORÇA | J13: ESTR. DA GÁVEA, 259 - PARTE | K13: ROCINHA | L13: 140 | N13: =IFERROR(VLOOKUP(O13,Apoio!A:B,2,0),"") | O13: =IFERROR(VLOOKUP(C13,'[1]TB DIN'!$B:$D,3,0),"AGUARDANDO ANEXO") -> 0 | P13: =IFERROR(VLOOKUP(C13,'[1]TB DIN INCLUIDOS'!$B:$H,3,0),"AGUARDANDO ANEXO") -> 0 | Q13: {=_xlfn.IFS((P13>N13),(N13*2),(P13<=N13),(P13*2))} -> 0 | S13: =IFERROR(VLOOKUP(T13,Apoio!A:B,2,0),"") -> 3 | T13: 54 | U13: =IFERROR(VLOOKUP(C13,'[1]TB DIN INCLUIDOS'!$B:$H,4,0),"AGUARDANDO ANEXO") -> 0 | V13: {=_xlfn.IFS((U13>S13),(S13*2),(U13<=S13),(U13*2))} -> 0 | X13: =IFERROR(VLOOKUP(Y13,Apoio!A:B,2,0),"") -> 2 | Y13: =IFERROR(VLOOKUP(C13,'[1]TB DIN'!$B:$H,5,0),"AGUARDANDO ANEXO") -> 42 | Z13: =IFERROR(VLOOKUP(C13,'[1]TB DIN INCLUIDOS'!$B:$H,5,0),"AGUARDANDO ANEXO") -> 1 | AA13: {=_xlfn.IFS((Z13>X13),(X13*2),(Z13<=X13),(Z13*2))} -> 2 | AC13: =IFERROR(VLOOKUP(AD13,Apoio!A:B,2,0),"") -> 2 | AD13: =IFERROR(VLOOKUP(C13,'[1]TB DIN'!$B:$H,6,0),"AGUARDANDO ANEXO") -> 41 | AE13: =IFERROR(VLOOKUP(C13,'[1]TB DIN INCLUIDOS'!$B:$H,6,0),"AGUARDANDO ANEXO") -> 1 | AF13: {=_xlfn.IFS((AE13>AC13),(AC13*2),(AE13<=AC13),(AE13*2))} -> 2 | AH13: =SUM(O13,T13,Y13,AD13) -> 137 | AI13: =SUM(P13,U13,Z13,AE13) -> 2 | AJ13: =SUM(Q13,V13,AA13,AF13) -> 4 | AK13: =IF(L13-AH13-Q13-V13-AA13-AF13>0,L13-AH13-Q13-V13-AA13-AF13,0) -> 0 | AL13: =IF(L13-O13-Q13-T13-V13-Y13-AA13-AD13-AF13<0,L13-O13-Q13-T13-V13-Y13-AA13-AD13-AF13,0) -> -1 | AM13: manutenção | AN13: =VLOOKUP(C13,'[2]MARÇO-2024'!$B:$M,12,0) -> 137 | AO13: =AN13-AH13 -> 0 | AP13: =IF(AH13>L13,"Qt de aluno maior que a meta","")
A14: 2 | B14: 4 | C14: 2004 | D14: 33095450 | E14: 42564773000140 | F14: 021138 | G14: CP AÇÃO SOCIAL PADRE ANCHIETA - ASPA | H14: AÇÃO SOCIAL PADRE ANCHIETA ASPA | I14: AÇÃO SOCIAL PADRE ANCHIETA - ASPA | J14: TRAVESSA LUZ, 13 | K14: ROCINHA | L14: 160 | N14: =IFERROR(VLOOKUP(O14,Apoio!A:B,2,0),"") | O14: =IFERROR(VLOOKUP(C14,'[1]TB DIN'!$B:$D,3,0),"AGUARDANDO ANEXO") -> 0 | P14: =IFERROR(VLOOKUP(C14,'[1]TB DIN INCLUIDOS'!$B:$H,3,0),"AGUARDANDO ANEXO") -> 0 | Q14: {=_xlfn.IFS((P14>N14),(N14*2),(P14<=N14),(P14*2))} -> 0 | S14: =IFERROR(VLOOKUP(T14,Apoio!A:B,2,0),"") -> 1 | T14: =IFERROR(VLOOKUP(C14,'[1]TB DIN'!$B:$H,4,0),"AGUARDANDO ANEXO") -> 24 | U14: =IFERROR(VLOOKUP(C14,'[1]TB DIN INCLUIDOS'!$B:$H,4,0),"AGUARDANDO ANEXO") -> 0 | V14: {=_xlfn.IFS((U14>S14),(S14*2),(U14<=S14),(U14*2))} -> 0 | X14: =IFERROR(VLOOKUP(Y14,Apoio!A:B,2,0),"") -> 3 | Y14: 64 | Z14: 4 | AA14: {=_xlfn.IFS((Z14>X14),(X14*2),(Z14<=X14),(Z14*2))} -> 6 | AC14: =IFERROR(VLOOKUP(AD14,Apoio!A:B,2,0),"") -> 3 | AD14: =IFERROR(VLOOKUP(C14,'[1]TB DIN'!$B:$H,6,0),"AGUARDANDO ANEXO") -> 67 | AE14: =IFERROR(VLOOKUP(C14,'[1]TB DIN INCLUIDOS'!$B:$H,6,0),"AGUARDANDO ANEXO") -> 1 | AF14: {=_xlfn.IFS((AE14>AC14),(AC14*2),(AE14<=AC14),(AE14*2))} -> 2 | AH14: =SUM(O14,T14,Y14,AD14) -> 155 | AI14: =SUM(P14,U14,Z14,AE14) -> 5 | AJ14: =SUM(Q14,V14,AA14,AF14) -> 8 | AK14: =IF(L14-AH14-Q14-V14-AA14-AF14>0,L14-AH14-Q14-V14-AA14-AF14,0) -> 0 | AL14: =IF(L14-O14-Q14-T14-V14-Y14-AA14-AD14-AF14<0,L14-O14-Q14-T14-V14-Y14-AA14-AD14-AF14,0) -> -3 | AM14: manutenção c/ redução da meta | AN14: =VLOOKUP(C14,'[2]MARÇO-2024'!$B:$M,12,0) -> 154 | AO14: =AN14-AH14 -> -1 | AP14: =IF(AH14>L14,"Qt de aluno maior que a meta","")
A15: 2 | B15: 5 | C15: 2005 | D15: 33096414 | E15: 00148879000113 | F15: 020268 | G15: CP ESCOLA COMUNITÁRIA DO CANTAGALO | H15: ESCOLA COMUNITÁRIA DO CANTAGALO | I15: ESCOLA COMUNITÁRIA DO CANTAGALO | J15: RUA SAINT ROMAIN, 200/RUA CÂNDIDO PORTINARI, 05 | K15: COPACABANA | L15: 72 | N15: =IFERROR(VLOOKUP(O15,Apoio!A:B,2,0),"") | O15: =IFERROR(VLOOKUP(C15,'[1]TB DIN'!$B:$D,3,0),"AGUARDANDO ANEXO") -> 0 | P15: =IFERROR(VLOOKUP(C15,'[1]TB DIN INCLUIDOS'!$B:$H,3,0),"AGUARDANDO ANEXO") -> 0 | Q15: {=_xlfn.IFS((P15>N15),(N15*2),(P15<=N15),(P15*2))} -> 0 | S15: =IFERROR(VLOOKUP(T15,Apoio!A:B,2,0),"") | T15: =IFERROR(VLOOKUP(C15,'[1]TB DIN'!$B:$H,4,0),"AGUARDANDO ANEXO") -> 0 | U15: =IFERROR(VLOOKUP(C15,'[1]TB DIN INCLUIDOS'!$B:$H,4,0),"AGUARDANDO ANEXO") -> 0 | V15: {=_xlfn.IFS((U15>S15),(S15*2),(U15<=S15),(U15*2))} -> 0 | X15: =IFERROR(VLOOKUP(Y15,Apoio!A:B,2,0),"") -> 2 | Y15: 32 | Z15: =IFERROR(VLOOKUP(C15,'[1]TB DIN INCLUIDOS'!$B:$H,5,0),"AGUARDANDO ANEXO") -> 0 | AA15: {=_xlfn.IFS((Z15>X15),(X15*2),(Z15<=X15),(Z15*2))} -> 0 | AC15: =IFERROR(VLOOKUP(AD15,Apoio!A:B,2,0),"") -> 2 | AD15: 40 | AE15: =IFERROR(VLOOKUP(C15,'[1]TB DIN INCLUIDOS'!$B:$H,6,0),"AGUARDANDO ANEXO") -> 0 | AF15: {=_xlfn.IFS((AE15>AC15),(AC15*2),(AE15<=AC15),(AE15*2))} -> 0 | AH15: =SUM(O15,T15,Y15,AD15) -> 72 | AI15: =SUM(P15,U15,Z15,AE15) -> 0 | AJ15: =SUM(Q15,V15,AA15,AF15) -> 0 | AK15: =IF(L15-AH15-Q15-V15-AA15-AF15>0,L15-AH15-Q15-V15-AA15-AF15,0) -> 0 | AL15: =IF(L15-O15-Q15-T15-V15-Y15-AA15-AD15-AF15<0,L15-O15-Q15-T15-V15-Y15-AA15-AD15-AF15,0) -> 0 | AM15: manutenção | AN15: =VLOOKUP(C15,'[2]MARÇO-2024'!$B:$M,12,0) -> 72 | AO15: =AN15-AH15 -> 0 | AP15: =IF(AH15>L15,"Qt de aluno maior que a meta","")
A16: 2 | B16: 6 | C16: 2006 | D16: 33096422 | E16: 32154197000100 | F16: 020451 | G16: CP CRECHE PRÉ-ESCOLA COMUNITÁRIA DOIS IRMÃOS | H16: CRECHE PRÉ-ESCOLA COMUNITÁRIA DOIS IRMÃOS | I16: CRECHE PRÉ-ESCOLA COMUNITÁRIA DOIS IRMÃOS | J16: EST. DA GÁVEA, 325 - BECO 1-CASA 30 | K16: ROCINHA | L16: 75 | N16: =IFERROR(VLOOKUP(O16,Apoio!A:B,2,0),"") | O16: =IFERROR(VLOOKUP(C16,'[1]TB DIN'!$B:$D,3,0),"AGUARDANDO ANEXO") -> 0 | P16: =IFERROR(VLOOKUP(C16,'[1]TB DIN INCLUIDOS'!$B:$H,3,0),"AGUARDANDO ANEXO") -> 0 | Q16: {=_xlfn.IFS((P16>N16),(N16*2),(P16<=N16),(P16*2))} -> 0 | S16: =IFERROR(VLOOKUP(T16,Apoio!A:B,2,0),"") -> 1 | T16: =IFERROR(VLOOKUP(C16,'[1]TB DIN'!$B:$H,4,0),"AGUARDANDO ANEXO") -> 25 | U16: =IFERROR(VLOOKUP(C16,'[1]TB DIN INCLUIDOS'!$B:$H,4,0),"AGUARDANDO ANEXO") -> 0 | V16: {=_xlfn.IFS((U16>S16),(S16*2),(U16<=S16),(U16*2))} -> 0 | X16: =IFERROR(VLOOKUP(Y16,Apoio!A:B,2,0),"") -> 1 | Y16: 25 | Z16: =IFERROR(VLOOKUP(C16,'[1]TB DIN INCLUIDOS'!$B:$H,5,0),"AGUARDANDO ANEXO") -> 1 | AA16: {=_xlfn.IFS((Z16>X16),(X16*2),(Z16<=X16),(Z16*2))} -> 2 | AC16: =IFERROR(VLOOKUP(AD16,Apoio!A:B,2,0),"") -> 1 | AD16: =IFERROR(VLOOKUP(C16,'[1]TB DIN'!$B:$H,6,0),"AGUARDANDO ANEXO") -> 23 | AE16: =IFERROR(VLOOKUP(C16,'[1]TB DIN INCLUIDOS'!$B:$H,6,0),"AGUARDANDO ANEXO") -> 1 | AF16: {=_xlfn.IFS((AE16>AC16),(AC16*2),(AE16<=AC16),(AE16*2))} -> 2 | AH16: =SUM(O16,T16,Y16,AD16) -> 73 | AI16: =SUM(P16,U16,Z16,AE16) -> 2 | AJ16: =SUM(Q16,V16,AA16,AF16) -> 4 | AK16: =IF(L16-AH16-Q16-V16-AA16-AF16>0,L16-AH16-Q16-V16-AA16-AF16,0) -> 0 | AL16: =IF(L16-O16-Q16-T16-V16-Y16-AA16-AD16-AF16<0,L16-O16-Q16-T16-V16-Y16-AA16-AD16-AF16,0) -> -2 | AM16: manutenção | AN16: =VLOOKUP(C16,'[2]MARÇO-2024'!$B:$M,12,0) -> 73 | AO16: =AN16-AH16 -> 0 | AP16: =IF(AH16>L16,"Qt de aluno maior que a meta","")
A17: 2 | B17: 7 | C17: 2009 | D17: 33108064 | E17: 33892738000160 | F17: 020441 | G17: CP ABRIGO TERESA DE JESUS | H17: ABRIGO TERESA DE JESUS | I17: ABRIGO TERESA DE JESUS | J17: RUA IBITURUNA, 53 | K17: TIJUCA | L17: 96 | N17: =IFERROR(VLOOKUP(O17,Apoio!A:B,2,0),"") | O17: =IFERROR(VLOOKUP(C17,'[1]TB DIN'!$B:$D,3,0),"AGUARDANDO ANEXO") -> 0 | P17: =IFERROR(VLOOKUP(C17,'[1]TB DIN INCLUIDOS'!$B:$H,3,0),"AGUARDANDO ANEXO") -> 0 | Q17: {=_xlfn.IFS((P17>N17),(N17*2),(P17<=N17),(P17*2))} -> 0 | S17: =IFERROR(VLOOKUP(T17,Apoio!A:B,2,0),"") | T17: =IFERROR(VLOOKUP(C17,'[1]TB DIN'!$B:$H,4,0),"AGUARDANDO ANEXO") -> 0 | U17: =IFERROR(VLOOKUP(C17,'[1]TB DIN INCLUIDOS'!$B:$H,4,0),"AGUARDANDO ANEXO") -> 0 | V17: {=_xlfn.IFS((U17>S17),(S17*2),(U17<=S17),(U17*2))} -> 0 | X17: =IFERROR(VLOOKUP(Y17,Apoio!A:B,2,0),"") -> 2 | Y17: 49 | Z17: =IFERROR(VLOOKUP(C17,'[1]TB DIN INCLUIDOS'!$B:$H,5,0),"AGUARDANDO ANEXO") -> 0 | AA17: {=_xlfn.IFS((Z17>X17),(X17*2),(Z17<=X17),(Z17*2))} -> 0 | AC17: =IFERROR(VLOOKUP(AD17,Apoio!A:B,2,0),"") -> 2 | AD17: 46 | AE17: 3 | AF17: {=_xlfn.IFS((AE17>AC17),(AC17*2),(AE17<=AC17),(AE17*2))} -> 4 | AH17: =SUM(O17,T17,Y17,AD17) -> 95 | AI17: =SUM(P17,U17,Z17,AE17) -> 3 | AJ17: =SUM(Q17,V17,AA17,AF17) -> 4 | AK17: =IF(L17-AH17-Q17-V17-AA17-AF17>0,L17-AH17-Q17-V17-AA17-AF17,0) -> 0 | AL17: =IF(L17-O17-Q17-T17-V17-Y17-AA17-AD17-AF17<0,L17-O17-Q17-T17-V17-Y17-AA17-AD17-AF17,0) -> -3 | AM17: manutenção | AN17: =VLOOKUP(C17,'[2]MARÇO-2024'!$B:$M,12,0) -> 94 | AO17: =AN17-AH17 -> -1 | AP17: =IF(AH17>L17,"Qt de aluno maior que a meta","")
A18: 2 | B18: 8 | C18: 2010 | D18: 33113777 | E18: 29014008000199 | F18: 020430 | G18: CP CRECHE PATINHO FELIZ | H18: CRECHE PATINHO FELIZ | I18: INATOS - INSTITUTO NACIONAL DE ASSIS. TRABALHO, OPORTUNIDADES E SAÚDE | J18: RUA ARMANDO DE ALBUQUERQUE, 168 | K18: VILA ISABEL | L18: 170 | N18: =IFERROR(VLOOKUP(O18,Apoio!A:B,2,0),"") | O18: =IFERROR(VLOOKUP(C18,'[1]TB DIN'!$B:$D,3,0),"AGUARDANDO ANEXO") -> 0 | P18: =IFERROR(VLOOKUP(C18,'[1]TB DIN INCLUIDOS'!$B:$H,3,0),"AGUARDANDO ANEXO") -> 0 | Q18: {=_xlfn.IFS((P18>N18),(N18*2),(P18<=N18),(P18*2))} -> 0 | S18: =IFERROR(VLOOKUP(T18,Apoio!A:B,2,0),"") -> 3 | T18: =IFERROR(VLOOKUP(C18,'[1]TB DIN'!$B:$H,4,0),"AGUARDANDO ANEXO") -> 57 | U18: =IFERROR(VLOOKUP(C18,'[1]TB DIN INCLUIDOS'!$B:$H,4,0),"AGUARDANDO ANEXO") -> 1 | V18: {=_xlfn.IFS((U18>S18),(S18*2),(U18<=S18),(U18*2))} -> 2 | X18: =IFERROR(VLOOKUP(Y18,Apoio!A:B,2,0),"") -> 3 | Y18: 60 | Z18: 1 | AA18: {=_xlfn.IFS((Z18>X18),(X18*2),(Z18<=X18),(Z18*2))} -> 2 | AC18: =IFERROR(VLOOKUP(AD18,Apoio!A:B,2,0),"") -> 3 | AD18: =IFERROR(VLOOKUP(C18,'[1]TB DIN'!$B:$H,6,0),"AGUARDANDO ANEXO") -> 54 | AE18: 2 | AF18: {=_xlfn.IFS((AE18>AC18),(AC18*2),(AE18<=AC18),(AE18*2))} -> 4 | AH18: =SUM(O18,T18,Y18,AD18) -> 171 | AI18: =SUM(P18,U18,Z18,AE18) -> 4 | AJ18: =SUM(Q18,V18,AA18,AF18) -> 8 | AK18: =IF(L18-AH18-Q18-V18-AA18-AF18>0,L18-AH18-Q18-V18-AA18-AF18,0) -> 0 | AL18: =IF(L18-O18-Q18-T18-V18-Y18-AA18-AD18-AF18<0,L18-O18-Q18-T18-V18-Y18-AA18-AD18-AF18,0) -> -9 | AM18: manutenção | AN18: =VLOOKUP(C18,'[2]MARÇO-2024'!$B:$M,12,0) -> 170 | AO18: =AN18-AH18 -> -1 | AP18: =IF(AH18>L18,"Qt de aluno maior que a meta","") -> Qt de aluno maior que a meta
A19: 2 | B19: 9 | C19: 2011 | D19: 33114404 | E19: 33585407000187 | F19: 020373 | G19: CP SOCIEDADE CIVIL DE ASSISTÊNCIA A MENORES - CASA DA DINDA | H19: SOCIEDADE CIVIL DE ASSISTÊNCIA A MENORES - CASA DA DINDA | I19: SOCIEDADE CIVIL DE ASSISTÊNCIA A MENORES - CASA DA DINDA | J19: RUA PETROCOCHINO, 74 | K19: VILA ISABEL | L19: 45 | N19: =IFERROR(VLOOKUP(O19,Apoio!A:B,2,0),"") | O19: =IFERROR(VLOOKUP(C19,'[1]TB DIN'!$B:$D,3,0),"AGUARDANDO ANEXO") -> 0 | P19: =IFERROR(VLOOKUP(C19,'[1]TB DIN INCLUIDOS'!$B:$H,3,0),"AGUARDANDO ANEXO") -> 0 | Q19: {=_xlfn.IFS((P19>N19),(N19*2),(P19<=N19),(P19*2))} -> 0 | S19: =IFERROR(VLOOKUP(T19,Apoio!A:B,2,0),"") -> 1 | T19: =IFERROR(VLOOKUP(C19,'[1]TB DIN'!$B:$H,4,0),"AGUARDANDO ANEXO") -> 17 | U19: =IFERROR(VLOOKUP(C19,'[1]TB DIN INCLUIDOS'!$B:$H,4,0),"AGUARDANDO ANEXO") -> 0 | V19: {=_xlfn.IFS((U19>S19),(S19*2),(U19<=S19),(U19*2))} -> 0 | X19: =IFERROR(VLOOKUP(Y19,Apoio!A:B,2,0),"") -> 1 | Y19: 17 | Z19: =IFERROR(VLOOKUP(C19,'[1]TB DIN INCLUIDOS'!$B:$H,5,0),"AGUARDANDO ANEXO") -> 0 | AA19: {=_xlfn.IFS((Z19>X19),(X19*2),(Z19<=X19),(Z19*2))} -> 0 | AC19: =IFERROR(VLOOKUP(AD19,Apoio!A:B,2,0),"") -> 1 | AD19: =IFERROR(VLOOKUP(C19,'[1]TB DIN'!$B:$H,6,0),"AGUARDANDO ANEXO") -> 11 | AE19: 2 | AF19: {=_xlfn.IFS((AE19>AC19),(AC19*2),(AE19<=AC19),(AE19*2))} -> 2 | AH19: =SUM(O19,T19,Y19,AD19) -> 45 | AI19: =SUM(P19,U19,Z19,AE19) -> 2 | AJ19: =SUM(Q19,V19,AA19,AF19) -> 2 | AK19: =IF(L19-AH19-Q19-V19-AA19-AF19>0,L19-AH19-Q19-V19-AA19-AF19,0) -> 0 | AL19: =IF(L19-O19-Q19-T19-V19-Y19-AA19-AD19-AF19<0,L19-O19-Q19-T19-V19-Y19-AA19-AD19-AF19,0) -> -2 | AM19: manutenção | AN19: =VLOOKUP(C19,'[2]MARÇO-2024'!$B:$M,12,0) -> 45 | AO19: =AN19-AH19 -> 0 | AP19: =IF(AH19>L19,"Qt de aluno maior que a meta","")
A20: 2 | B20: 10 | C20: 2012 | D20: 33114455 | E20: 73791337000138 | F20: 020454 | G20: CP GRUPO COMUNITÁRIO CRECHE ESCOLA TIA MAURA | H20: GRUPO COMUNITÁRIO CRECHE ESCOLA TIA MAURA | I20: GRUPO COMUNITÁRIO CRECHE ESCOLA TIA MAURA | J20: ESTR. DAS CANOAS, 720 | K20: SÃO CONRADO | L20: 70 | N20: =IFERROR(VLOOKUP(O20,Apoio!A:B,2,0),"") | O20: =IFERROR(VLOOKUP(C20,'[1]TB DIN'!$B:$D,3,0),"AGUARDANDO ANEXO") -> 0 | P20: =IFERROR(VLOOKUP(C20,'[1]TB DIN INCLUIDOS'!$B:$H,3,0),"AGUARDANDO ANEXO") -> 0 | Q20: {=_xlfn.IFS((P20>N20),(N20*2),(P20<=N20),(P20*2))} -> 0 | S20: =IFERROR(VLOOKUP(T20,Apoio!A:B,2,0),"") -> 1 | T20: =IFERROR(VLOOKUP(C20,'[1]TB DIN'!$B:$H,4,0),"AGUARDANDO ANEXO") -> 24 | U20: =IFERROR(VLOOKUP(C20,'[1]TB DIN INCLUIDOS'!$B:$H,4,0),"AGUARDANDO ANEXO") -> 0 | V20: {=_xlfn.IFS((U20>S20),(S20*2),(U20<=S20),(U20*2))} -> 0 | X20: =IFERROR(VLOOKUP(Y20,Apoio!A:B,2,0),"") -> 1 | Y20: =IFERROR(VLOOKUP(C20,'[1]TB DIN'!$B:$H,5,0),"AGUARDANDO ANEXO") -> 20 | Z20: =IFERROR(VLOOKUP(C20,'[1]TB DIN INCLUIDOS'!$B:$H,5,0),"AGUARDANDO ANEXO") -> 0 | AA20: {=_xlfn.IFS((Z20>X20),(X20*2),(Z20<=X20),(Z20*2))} -> 0 | AC20: =IFERROR(VLOOKUP(AD20,Apoio!A:B,2,0),"") -> 2 | AD20: =IFERROR(VLOOKUP(C20,'[1]TB DIN'!$B:$H,6,0),"AGUARDANDO ANEXO") -> 26 | AE20: =IFERROR(VLOOKUP(C20,'[1]TB DIN INCLUIDOS'!$B:$H,6,0),"AGUARDANDO ANEXO") -> 0 | AF20: {=_xlfn.IFS((AE20>AC20),(AC20*2),(AE20<=AC20),(AE20*2))} -> 0 | AH20: =SUM(O20,T20,Y20,AD20) -> 70 | AI20: =SUM(P20,U20,Z20,AE20) -> 0 | AJ20: =SUM(Q20,V20,AA20,AF20) -> 0 | AK20: =IF(L20-AH20-Q20-V20-AA20-AF20>0,L20-AH20-Q20-V20-AA20-AF20,0) -> 0 | AL20: =IF(L20-O20-Q20-T20-V20-Y20-AA20-AD20-AF20<0,L20-O20-Q20-T20-V20-Y20-AA20-AD20-AF20,0) -> 0 | AM20: manutenção | AN20: =VLOOKUP(C20,'[2]MARÇO-2024'!$B:$M,12,0) -> 70 | AO20: =AN20-AH20 -> 0 | AP20: =IF(AH20>L20,"Qt de aluno maior que a meta","")
A21: 2 | B21: 11 | C21: 2013 | D21: 33114480 | E21: 74032871000123 | F21: 020114 | G21: CP CENTRO DE EDUCAÇÃO INFANTIL CRISTO REDENTOR | H21: CENTRO DE EDUCAÇÃO INFANTIL CRISTO REDENTOR | I21: ASSOCIAÇÃO PALOTINA | J21: RUA INDIANA, 59 | K21: COSME VELHO | L21: 65 | N21: =IFERROR(VLOOKUP(O21,Apoio!A:B,2,0),"") | O21: =IFERROR(VLOOKUP(C21,'[1]TB DIN'!$B:$D,3,0),"AGUARDANDO ANEXO") -> 0 | P21: =IFERROR(VLOOKUP(C21,'[1]TB DIN INCLUIDOS'!$B:$H,3,0),"AGUARDANDO ANEXO") -> 0 | Q21: {=_xlfn.IFS((P21>N21),(N21*2),(P21<=N21),(P21*2))} -> 0 | S21: =IFERROR(VLOOKUP(T21,Apoio!A:B,2,0),"") | T21: =IFERROR(VLOOKUP(C21,'[1]TB DIN'!$B:$H,4,0),"AGUARDANDO ANEXO") -> 0 | U21: =IFERROR(VLOOKUP(C21,'[1]TB DIN INCLUIDOS'!$B:$H,4,0),"AGUARDANDO ANEXO") -> 0 | V21: {=_xlfn.IFS((U21>S21),(S21*2),(U21<=S21),(U21*2))} -> 0 | X21: =IFERROR(VLOOKUP(Y21,Apoio!A:B,2,0),"") -> 2 | Y21: =IFERROR(VLOOKUP(C21,'[1]TB DIN'!$B:$H,5,0),"AGUARDANDO ANEXO") -> 32 | Z21: =IFERROR(VLOOKUP(C21,'[1]TB DIN INCLUIDOS'!$B:$H,5,0),"AGUARDANDO ANEXO") -> 0 | AA21: {=_xlfn.IFS((Z21>X21),(X21*2),(Z21<=X21),(Z21*2))} -> 0 | AC21: =IFERROR(VLOOKUP(AD21,Apoio!A:B,2,0),"") -> 2 | AD21: =IFERROR(VLOOKUP(C21,'[1]TB DIN'!$B:$H,6,0),"AGUARDANDO ANEXO") -> 27 | AE21: =IFERROR(VLOOKUP(C21,'[1]TB DIN INCLUIDOS'!$B:$H,6,0),"AGUARDANDO ANEXO") -> 0 | AF21: {=_xlfn.IFS((AE21>AC21),(AC21*2),(AE21<=AC21),(AE21*2))} -> 0 | AH21: =SUM(O21,T21,Y21,AD21) -> 59 | AI21: =SUM(P21,U21,Z21,AE21) -> 0 | AJ21: =SUM(Q21,V21,AA21,AF21) -> 0 | AK21: =IF(L21-AH21-Q21-V21-AA21-AF21>0,L21-AH21-Q21-V21-AA21-AF21,0) -> 6 | AL21: =IF(L21-O21-Q21-T21-V21-Y21-AA21-AD21-AF21<0,L21-O21-Q21-T21-V21-Y21-AA21-AD21-AF21,0) -> 0 | AM21: manutenção | AN21: =VLOOKUP(C21,'[2]MARÇO-2024'!$B:$M,12,0) -> 61 | AO21: =AN21-AH21 -> 2 | AP21: =IF(AH21>L21,"Qt de aluno maior que a meta","")
A22: 2 | B22: 12 | C22: 2014 | D22: 33114501 | E22: 34056630000108 | F22: 020461 | G22: CP CRUZADA PELA INFÂNCIA DO LEME | H22: CRUZADA PELA INFÂNCIA DO LEME | I22: CRUZADA PELA INFÂNCIA DO LEME | J22: RUA COELHO CINTRA, 380 | K22: COPACABANA | L22: 60 | N22: =IFERROR(VLOOKUP(O22,Apoio!A:B,2,0),"") | O22: =IFERROR(VLOOKUP(C22,'[1]TB DIN'!$B:$D,3,0),"AGUARDANDO ANEXO") -> 0 | P22: =IFERROR(VLOOKUP(C22,'[1]TB DIN INCLUIDOS'!$B:$H,3,0),"AGUARDANDO ANEXO") -> 0 | Q22: {=_xlfn.IFS((P22>N22),(N22*2),(P22<=N22),(P22*2))} -> 0 | S22: =IFERROR(VLOOKUP(T22,Apoio!A:B,2,0),"") -> 1 | T22: =IFERROR(VLOOKUP(C22,'[1]TB DIN'!$B:$H,4,0),"AGUARDANDO ANEXO") -> 21 | U22: =IFERROR(VLOOKUP(C22,'[1]TB DIN INCLUIDOS'!$B:$H,4,0),"AGUARDANDO ANEXO") -> 0 | V22: {=_xlfn.IFS((U22>S22),(S22*2),(U22<=S22),(U22*2))} -> 0 | X22: =IFERROR(VLOOKUP(Y22,Apoio!A:B,2,0),"") -> 1 | Y22: 22 | Z22: =IFERROR(VLOOKUP(C22,'[1]TB DIN INCLUIDOS'!$B:$H,5,0),"AGUARDANDO ANEXO") -> 0 | AA22: {=_xlfn.IFS((Z22>X22),(X22*2),(Z22<=X22),(Z22*2))} -> 0 | AC22: =IFERROR(VLOOKUP(AD22,Apoio!A:B,2,0),"") -> 1 | AD22: =IFERROR(VLOOKUP(C22,'[1]TB DIN'!$B:$H,6,0),"AGUARDANDO ANEXO") -> 15 | AE22: =IFERROR(VLOOKUP(C22,'[1]TB DIN INCLUIDOS'!$B:$H,6,0),"AGUARDANDO ANEXO") -> 2 | AF22: {=_xlfn.IFS((AE22>AC22),(AC22*2),(AE22<=AC22),(AE22*2))} -> 2 | AH22: =SUM(O22,T22,Y22,AD22) -> 58 | AI22: =SUM(P22,U22,Z22,AE22) -> 2 | AJ22: =SUM(Q22,V22,AA22,AF22) -> 2 | AK22: =IF(L22-AH22-Q22-V22-AA22-AF22>0,L22-AH22-Q22-V22-AA22-AF22,0) -> 0 | AL22: =IF(L22-O22-Q22-T22-V22-Y22-AA22-AD22-AF22<0,L22-O22-Q22-T22-V22-Y22-AA22-AD22-AF22,0) -> 0 | AM22: manutenção | AN22: =VLOOKUP(C22,'[2]MARÇO-2024'!$B:$M,12,0) -> 58 | AO22: =AN22-AH22 -> 0 | AP22: =IF(AH22>L22,"Qt de aluno maior que a meta","")
A23: 2 | B23: 13 | C23: 2015 | D23: 33114552 | E23: 34030585000104 | F23: 020087 | G23: CP CRECHE SANT ANNA | H23: CRECHE SANT’ANNA | I23: OBRA SOCIAL CRISTO REDENTOR | J23: RUA PROFESSOR LUIZ CANTANHEDE, 25 | K23: LARANJEIRAS | L23: 72 | N23: =IFERROR(VLOOKUP(O23,Apoio!A:B,2,0),"") | O23: =IFERROR(VLOOKUP(C23,'[1]TB DIN'!$B:$D,3,0),"AGUARDANDO ANEXO") -> 0 | P23: =IFERROR(VLOOKUP(C23,'[1]TB DIN INCLUIDOS'!$B:$H,3,0),"AGUARDANDO ANEXO") -> 0 | Q23: {=_xlfn.IFS((P23>N23),(N23*2),(P23<=N23),(P23*2))} -> 0 | S23: =IFERROR(VLOOKUP(T23,Apoio!A:B,2,0),"") | T23: =IFERROR(VLOOKUP(C23,'[1]TB DIN'!$B:$H,4,0),"AGUARDANDO ANEXO") -> 0 | U23: =IFERROR(VLOOKUP(C23,'[1]TB DIN INCLUIDOS'!$B:$H,4,0),"AGUARDANDO ANEXO") -> 0 | V23: {=_xlfn.IFS((U23>S23),(S23*2),(U23<=S23),(U23*2))} -> 0 | X23: =IFERROR(VLOOKUP(Y23,Apoio!A:B,2,0),"") -> 2 | Y23: =IFERROR(VLOOKUP(C23,'[1]TB DIN'!$B:$H,5,0),"AGUARDANDO ANEXO") -> 27 | Z23: 1 | AA23: {=_xlfn.IFS((Z23>X23),(X23*2),(Z23<=X23),(Z23*2))} -> 2 | AC23: =IFERROR(VLOOKUP(AD23,Apoio!A:B,2,0),"") -> 2 | AD23: =IFERROR(VLOOKUP(C23,'[1]TB DIN'!$B:$H,6,0),"AGUARDANDO ANEXO") -> 45 | AE23: =IFERROR(VLOOKUP(C23,'[1]TB DIN INCLUIDOS'!$B:$H,6,0),"AGUARDANDO ANEXO") -> 1 | AF23: {=_xlfn.IFS((AE23>AC23),(AC23*2),(AE23<=AC23),(AE23*2))} -> 2 | AH23: =SUM(O23,T23,Y23,AD23) -> 72 | AI23: =SUM(P23,U23,Z23,AE23) -> 2 | AJ23: =SUM(Q23,V23,AA23,AF23) -> 4 | AK23: =IF(L23-AH23-Q23-V23-AA23-AF23>0,L23-AH23-Q23-V23-AA23-AF23,0) -> 0 | AL23: =IF(L23-O23-Q23-T23-V23-Y23-AA23-AD23-AF23<0,L23-O23-Q23-T23-V23-Y23-AA23-AD23-AF23,0) -> -4 | AM23: manutenção | AN23: =VLOOKUP(C23,'[2]MARÇO-2024'!$B:$M,12,0) -> 72 | AO23: =AN23-AH23 -> 0 | AP23: =IF(AH23>L23,"Qt de aluno maior que a meta","")
A24: 2 | B24: 14 | C24: 2016 | D24: 33116113 | E24: 33727009000158 | F24: 020187 | G24: CP CASA MATERNAL MELLO MATTOS | H24: CASA MATERNAL MELLO MATTOS | I24: ASSOCIAÇÃO TUTELAR DE MENORES | J24: RUA FARO, 80 | K24: JARDIM BOTÂNICO | L24: 120 | N24: =IFERROR(VLOOKUP(O24,Apoio!A:B,2,0),"") | O24: =IFERROR(VLOOKUP(C24,'[1]TB DIN'!$B:$D,3,0),"AGUARDANDO ANEXO") -> 0 | P24: =IFERROR(VLOOKUP(C24,'[1]TB DIN INCLUIDOS'!$B:$H,3,0),"AGUARDANDO ANEXO") -> 0 | Q24: {=_xlfn.IFS((P24>N24),(N24*2),(P24<=N24),(P24*2))} -> 0 | S24: =IFERROR(VLOOKUP(T24,Apoio!A:B,2,0),"") -> 2 | T24: 29 | U24: =IFERROR(VLOOKUP(C24,'[1]TB DIN INCLUIDOS'!$B:$H,4,0),"AGUARDANDO ANEXO") -> 0 | V24: {=_xlfn.IFS((U24>S24),(S24*2),(U24<=S24),(U24*2))} -> 0 | X24: =IFERROR(VLOOKUP(Y24,Apoio!A:B,2,0),"") -> 2 | Y24: 34 | Z24: =IFERROR(VLOOKUP(C24,'[1]TB DIN INCLUIDOS'!$B:$H,5,0),"AGUARDANDO ANEXO") -> 0 | AA24: {=_xlfn.IFS((Z24>X24),(X24*2),(Z24<=X24),(Z24*2))} -> 0 | AC24: =IFERROR(VLOOKUP(AD24,Apoio!A:B,2,0),"") -> 2 | AD24: =IFERROR(VLOOKUP(C24,'[1]TB DIN'!$B:$H,6,0),"AGUARDANDO ANEXO") -> 36 | AE24: 2 | AF24: {=_xlfn.IFS((AE24>AC24),(AC24*2),(AE24<=AC24),(AE24*2))} -> 4 | AH24: =SUM(O24,T24,Y24,AD24) -> 99 | AI24: =SUM(P24,U24,Z24,AE24) -> 2 | AJ24: =SUM(Q24,V24,AA24,AF24) -> 4 | AK24: =IF(L24-AH24-Q24-V24-AA24-AF24>0,L24-AH24-Q24-V24-AA24-AF24,0) -> 17 | AL24: =IF(L24-O24-Q24-T24-V24-Y24-AA24-AD24-AF24<0,L24-O24-Q24-T24-V24-Y24-AA24-AD24-AF24,0) -> 0 | AM24: manutenção c/ redução da meta | AN24: =VLOOKUP(C24,'[2]MARÇO-2024'!$B:$M,12,0) -> 95 | AO24: =AN24-AH24 -> -4 | AP24: =IF(AH24>L24,"Qt de aluno maior que a meta","")
A25: 2 | B25: 15 | C25: 2018 | D25: 33117870 | E25: 34125450000122 | F25: 020453 | G25: CP FUNDAÇÃO CASA SANTA IGNEZ | H25: FUNDAÇÃO CASA SANTA IGNEZ | I25: FUNDAÇÃO CASA SANTA IGNEZ | J25: RUA MERY PESSOA,91 | K25: GÁVEA | L25: 96 | N25: =IFERROR(VLOOKUP(O25,Apoio!A:B,2,0),"") | O25: =IFERROR(VLOOKUP(C25,'[1]TB DIN'!$B:$D,3,0),"AGUARDANDO ANEXO") -> 0 | P25: =IFERROR(VLOOKUP(C25,'[1]TB DIN INCLUIDOS'!$B:$H,3,0),"AGUARDANDO ANEXO") -> 0 | Q25: {=_xlfn.IFS((P25>N25),(N25*2),(P25<=N25),(P25*2))} -> 0 | S25: =IFERROR(VLOOKUP(T25,Apoio!A:B,2,0),"") | T25: =IFERROR(VLOOKUP(C25,'[1]TB DIN'!$B:$H,4,0),"AGUARDANDO ANEXO") -> 0 | U25: =IFERROR(VLOOKUP(C25,'[1]TB DIN INCLUIDOS'!$B:$H,4,0),"AGUARDANDO ANEXO") -> 0 | V25: {=_xlfn.IFS((U25>S25),(S25*2),(U25<=S25),(U25*2))} -> 0 | X25: =IFERROR(VLOOKUP(Y25,Apoio!A:B,2,0),"") -> 2 | Y25: =IFERROR(VLOOKUP(C25,'[1]TB DIN'!$B:$H,5,0),"AGUARDANDO ANEXO") -> 45 | Z25: =IFERROR(VLOOKUP(C25,'[1]TB DIN INCLUIDOS'!$B:$H,5,0),"AGUARDANDO ANEXO") -> 0 | AA25: {=_xlfn.IFS((Z25>X25),(X25*2),(Z25<=X25),(Z25*2))} -> 0 | AC25: =IFERROR(VLOOKUP(AD25,Apoio!A:B,2,0),"") -> 2 | AD25: 48 | AE25: =IFERROR(VLOOKUP(C25,'[1]TB DIN INCLUIDOS'!$B:$H,6,0),"AGUARDANDO ANEXO") -> 3 | AF25: {=_xlfn.IFS((AE25>AC25),(AC25*2),(AE25<=AC25),(AE25*2))} -> 4 | AH25: =SUM(O25,T25,Y25,AD25) -> 93 | AI25: =SUM(P25,U25,Z25,AE25) -> 3 | AJ25: =SUM(Q25,V25,AA25,AF25) -> 4 | AK25: =IF(L25-AH25-Q25-V25-AA25-AF25>0,L25-AH25-Q25-V25-AA25-AF25,0) -> 0 | AL25: =IF(L25-O25-Q25-T25-V25-Y25-AA25-AD25-AF25<0,L25-O25-Q25-T25-V25-Y25-AA25-AD25-AF25,0) -> -1 | AM25: manutenção | AN25: =VLOOKUP(C25,'[2]MARÇO-2024'!$B:$M,12,0) -> 94 | AO25: =AN25-AH25 -> 1 | AP25: =IF(AH25>L25,"Qt de aluno maior que a meta","")
A26: 2 | B26: 16 | C26: 2019 | D26: 33120927 | E26: 29259850000190 | F26: 020467 | G26: CP UNIDAS - OBRAS SOCIAIS UNIDAS DE SANTA MARTA | H26: UNIDAS - OBRAS SOCIAIS UNIDAS DE SANTA MARTA | I26: OBRAS SOCIAIS UNIDAS DE SANTA MARTA | J26: BECO DO JABUTI, 09 - MORRO SANTA MARTA | K26: BOTAFOGO | L26: 60 | N26: =IFERROR(VLOOKUP(O26,Apoio!A:B,2,0),"") | O26: =IFERROR(VLOOKUP(C26,'[1]TB DIN'!$B:$D,3,0),"AGUARDANDO ANEXO") -> 0 | P26: =IFERROR(VLOOKUP(C26,'[1]TB DIN INCLUIDOS'!$B:$H,3,0),"AGUARDANDO ANEXO") -> 0 | Q26: {=_xlfn.IFS((P26>N26),(N26*2),(P26<=N26),(P26*2))} -> 0 | S26: =IFERROR(VLOOKUP(T26,Apoio!A:B,2,0),"") -> 1 | T26: =IFERROR(VLOOKUP(C26,'[1]TB DIN'!$B:$H,4,0),"AGUARDANDO ANEXO") -> 18 | U26: =IFERROR(VLOOKUP(C26,'[1]TB DIN INCLUIDOS'!$B:$H,4,0),"AGUARDANDO ANEXO") -> 0 | V26: {=_xlfn.IFS((U26>S26),(S26*2),(U26<=S26),(U26*2))} -> 0 | X26: =IFERROR(VLOOKUP(Y26,Apoio!A:B,2,0),"") -> 1 | Y26: 21 | Z26: =IFERROR(VLOOKUP(C26,'[1]TB DIN INCLUIDOS'!$B:$H,5,0),"AGUARDANDO ANEXO") -> 0 | AA26: {=_xlfn.IFS((Z26>X26),(X26*2),(Z26<=X26),(Z26*2))} -> 0 | AC26: =IFERROR(VLOOKUP(AD26,Apoio!A:B,2,0),"") -> 1 | AD26: 17 | AE26: =IFERROR(VLOOKUP(C26,'[1]TB DIN INCLUIDOS'!$B:$H,6,0),"AGUARDANDO ANEXO") -> 0 | AF26: {=_xlfn.IFS((AE26>AC26),(AC26*2),(AE26<=AC26),(AE26*2))} -> 0 | AH26: =SUM(O26,T26,Y26,AD26) -> 56 | AI26: =SUM(P26,U26,Z26,AE26) -> 0 | AJ26: =SUM(Q26,V26,AA26,AF26) -> 0 | AK26: =IF(L26-AH26-Q26-V26-AA26-AF26>0,L26-AH26-Q26-V26-AA26-AF26,0) -> 4 | AL26: =IF(L26-O26-Q26-T26-V26-Y26-AA26-AD26-AF26<0,L26-O26-Q26-T26-V26-Y26-AA26-AD26-AF26,0) -> 0 | AM26: manutenção | AN26: =VLOOKUP(C26,'[2]MARÇO-2024'!$B:$M,12,0) -> 57 | AO26: =AN26-AH26 -> 1 | AP26: =IF(AH26>L26,"Qt de aluno maior que a meta","")
A27: 2 | B27: 17 | C27: 2020 | D27: 33120951 | E27: 34036194000105 | F27: 020457 | G27: CP CASA ESPÍRITA CRISTÃ MARIA DE NAZARÉ | H27: CASA ESPÍRITA CRISTÃ MARIA DE NAZARÉ | I27: CASA ESPÍRITA CRISTÃ MARIA DE NAZARÉ | J27: ESTR. DA GÁVEA, 262, QUARTEIRÃO 21, R. UM S/Nº | K27: ROCINHA | L27: 120 | N27: =IFERROR(VLOOKUP(O27,Apoio!A:B,2,0),"") -> 1 | O27: =IFERROR(VLOOKUP(C27,'[1]TB DIN'!$B:$D,3,0),"AGUARDANDO ANEXO") -> 11 | P27: =IFERROR(VLOOKUP(C27,'[1]TB DIN INCLUIDOS'!$B:$H,3,0),"AGUARDANDO ANEXO") -> 0 | Q27: {=_xlfn.IFS((P27>N27),(N27*2),(P27<=N27),(P27*2))} -> 0 | S27: =IFERROR(VLOOKUP(T27,Apoio!A:B,2,0),"") -> 2 | T27: =IFERROR(VLOOKUP(C27,'[1]TB DIN'!$B:$H,4,0),"AGUARDANDO ANEXO") -> 32 | U27: =IFERROR(VLOOKUP(C27,'[1]TB DIN INCLUIDOS'!$B:$H,4,0),"AGUARDANDO ANEXO") -> 0 | V27: {=_xlfn.IFS((U27>S27),(S27*2),(U27<=S27),(U27*2))} -> 0 | X27: =IFERROR(VLOOKUP(Y27,Apoio!A:B,2,0),"") -> 2 | Y27: =IFERROR(VLOOKUP(C27,'[1]TB DIN'!$B:$H,5,0),"AGUARDANDO ANEXO") -> 43 | Z27: =IFERROR(VLOOKUP(C27,'[1]TB DIN INCLUIDOS'!$B:$H,5,0),"AGUARDANDO ANEXO") -> 0 | AA27: {=_xlfn.IFS((Z27>X27),(X27*2),(Z27<=X27),(Z27*2))} -> 0 | AC27: =IFERROR(VLOOKUP(AD27,Apoio!A:B,2,0),"") -> 2 | AD27: =IFERROR(VLOOKUP(C27,'[1]TB DIN'!$B:$H,6,0),"AGUARDANDO ANEXO") -> 34 | AE27: =IFERROR(VLOOKUP(C27,'[1]TB DIN INCLUIDOS'!$B:$H,6,0),"AGUARDANDO ANEXO") -> 0 | AF27: {=_xlfn.IFS((AE27>AC27),(AC27*2),(AE27<=AC27),(AE27*2))} -> 0 | AH27: =SUM(O27,T27,Y27,AD27) -> 120 | AI27: =SUM(P27,U27,Z27,AE27) -> 0 | AJ27: =SUM(Q27,V27,AA27,AF27) -> 0 | AK27: =IF(L27-AH27-Q27-V27-AA27-AF27>0,L27-AH27-Q27-V27-AA27-AF27,0) -> 0 | AL27: =IF(L27-O27-Q27-T27-V27-Y27-AA27-AD27-AF27<0,L27-O27-Q27-T27-V27-Y27-AA27-AD27-AF27,0) -> 0 | AM27: manutenção | AN27: =VLOOKUP(C27,'[2]MARÇO-2024'!$B:$M,12,0) -> 120 | AO27: =AN27-AH27 -> 0 | AP27: =IF(AH27>L27,"Qt de aluno maior que a meta","")
A28: 2 | B28: 18 | C28: 2022 | D28: 33121940 | E28: 33593575027314 | F28: 020477 | G28: CP CRECHE CHAPEUZINHO MARROM | H28: CRECHE CHAPEUZINHO MARROM | I28: MITRA ARQUIEPISCOPAL DO RIO DE JANEIRO | J28: RUA JOAQUIM PIZARRO,63 | K28: TURANO / RIO COMPRIDO | L28: 42 | N28: =IFERROR(VLOOKUP(O28,Apoio!A:B,2,0),"") | O28: =IFERROR(VLOOKUP(C28,'[1]TB DIN'!$B:$D,3,0),"AGUARDANDO ANEXO") -> 0 | P28: =IFERROR(VLOOKUP(C28,'[1]TB DIN INCLUIDOS'!$B:$H,3,0),"AGUARDANDO ANEXO") -> 0 | Q28: {=_xlfn.IFS((P28>N28),(N28*2),(P28<=N28),(P28*2))} -> 0 | S28: =IFERROR(VLOOKUP(T28,Apoio!A:B,2,0),"") | T28: =IFERROR(VLOOKUP(C28,'[1]TB DIN'!$B:$H,4,0),"AGUARDANDO ANEXO") -> 0 | U28: =IFERROR(VLOOKUP(C28,'[1]TB DIN INCLUIDOS'!$B:$H,4,0),"AGUARDANDO ANEXO") -> 0 | V28: {=_xlfn.IFS((U28>S28),(S28*2),(U28<=S28),(U28*2))} -> 0 | X28: =IFERROR(VLOOKUP(Y28,Apoio!A:B,2,0),"") -> 1 | Y28: 21 | Z28: =IFERROR(VLOOKUP(C28,'[1]TB DIN INCLUIDOS'!$B:$H,5,0),"AGUARDANDO ANEXO") -> 0 | AA28: {=_xlfn.IFS((Z28>X28),(X28*2),(Z28<=X28),(Z28*2))} -> 0 | AC28: =IFERROR(VLOOKUP(AD28,Apoio!A:B,2,0),"") -> 1 | AD28: 21 | AE28: =IFERROR(VLOOKUP(C28,'[1]TB DIN INCLUIDOS'!$B:$H,6,0),"AGUARDANDO ANEXO") -> 0 | AF28: {=_xlfn.IFS((AE28>AC28),(AC28*2),(AE28<=AC28),(AE28*2))} -> 0 | AH28: =SUM(O28,T28,Y28,AD28) -> 42 | AI28: =SUM(P28,U28,Z28,AE28) -> 0 | AJ28: =SUM(Q28,V28,AA28,AF28) -> 0 | AK28: =IF(L28-AH28-Q28-V28-AA28-AF28>0,L28-AH28-Q28-V28-AA28-AF28,0) -> 0 | AL28: =IF(L28-O28-Q28-T28-V28-Y28-AA28-AD28-AF28<0,L28-O28-Q28-T28-V28-Y28-AA28-AD28-AF28,0) -> 0 | AM28: manutenção | AN28: =VLOOKUP(C28,'[2]MARÇO-2024'!$B:$M,12,0) -> 42 | AO28: =AN28-AH28 -> 0 | AP28: =IF(AH28>L28,"Qt de aluno maior que a meta","")
A29: 2 | B29: 19 | C29: 2024 | D29: 33122024 | E29: 31660004000120 | F29: 020444 | G29: CP CRECHE ESCADINHA DO SABER | H29: CRECHE ESCADINHA DO SABER | I29: ASSOCIAÇÃO DE MORADORES DO TIJUAÇU - AMOTI | J29: ESTR. DO TIJUAÇU, 32 | K29: ALTO DA BOA VISTA | L29: 45 | N29: =IFERROR(VLOOKUP(O29,Apoio!A:B,2,0),"") | O29: =IFERROR(VLOOKUP(C29,'[1]TB DIN'!$B:$D,3,0),"AGUARDANDO ANEXO") -> 0 | P29: =IFERROR(VLOOKUP(C29,'[1]TB DIN INCLUIDOS'!$B:$H,3,0),"AGUARDANDO ANEXO") -> 0 | Q29: {=_xlfn.IFS((P29>N29),(N29*2),(P29<=N29),(P29*2))} -> 0 | S29: =IFERROR(VLOOKUP(T29,Apoio!A:B,2,0),"") | T29: =IFERROR(VLOOKUP(C29,'[1]TB DIN'!$B:$H,4,0),"AGUARDANDO ANEXO") -> 0 | U29: =IFERROR(VLOOKUP(C29,'[1]TB DIN INCLUIDOS'!$B:$H,4,0),"AGUARDANDO ANEXO") -> 0 | V29: {=_xlfn.IFS((U29>S29),(S29*2),(U29<=S29),(U29*2))} -> 0 | X29: =IFERROR(VLOOKUP(Y29,Apoio!A:B,2,0),"") -> 1 | Y29: 9 | Z29: =IFERROR(VLOOKUP(C29,'[1]TB DIN INCLUIDOS'!$B:$H,5,0),"AGUARDANDO ANEXO") -> 0 | AA29: {=_xlfn.IFS((Z29>X29),(X29*2),(Z29<=X29),(Z29*2))} -> 0 | AC29: =IFERROR(VLOOKUP(AD29,Apoio!A:B,2,0),"") -> 1 | AD29: =IFERROR(VLOOKUP(C29,'[1]TB DIN'!$B:$H,6,0),"AGUARDANDO ANEXO") -> 10 | AE29: =IFERROR(VLOOKUP(C29,'[1]TB DIN INCLUIDOS'!$B:$H,6,0),"AGUARDANDO ANEXO") -> 0 | AF29: {=_xlfn.IFS((AE29>AC29),(AC29*2),(AE29<=AC29),(AE29*2))} -> 0 | AH29: =SUM(O29,T29,Y29,AD29) -> 19 | AI29: =SUM(P29,U29,Z29,AE29) -> 0 | AJ29: =SUM(Q29,V29,AA29,AF29) -> 0 | AK29: =IF(L29-AH29-Q29-V29-AA29-AF29>0,L29-AH29-Q29-V29-AA29-AF29,0) -> 26 | AL29: =IF(L29-O29-Q29-T29-V29-Y29-AA29-AD29-AF29<0,L29-O29-Q29-T29-V29-Y29-AA29-AD29-AF29,0) -> 0 | AM29: manutenção | AN29: =VLOOKUP(C29,'[2]MARÇO-2024'!$B:$M,12,0) -> 18 | AO29: =AN29-AH29 -> -1 | AP29: =IF(AH29>L29,"Qt de aluno maior que a meta","")
A30: 2 | B30: 20 | C30: 2025 | D30: 33122229 | E30: 34031807000103 | F30: 20249 | G30: CP CRECHE BEZERRA DE MENEZES - BOTAFOGO | H30: CRECHE BEZERRA DE MENEZES (BOTAFOGO) | I30: CENTRO ESPÍRITA CRISTÓFILOS | J30: RUA MARTINS FERREIRA, 57 | K30: BOTAFOGO | L30: 50 | N30: =IFERROR(VLOOKUP(O30,Apoio!A:B,2,0),"") -> 1 | O30: =IFERROR(VLOOKUP(C30,'[1]TB DIN'!$B:$D,3,0),"AGUARDANDO ANEXO") -> 3 | P30: =IFERROR(VLOOKUP(C30,'[1]TB DIN INCLUIDOS'!$B:$H,3,0),"AGUARDANDO ANEXO") -> 0 | Q30: {=_xlfn.IFS((P30>N30),(N30*2),(P30<=N30),(P30*2))} -> 0 | S30: =IFERROR(VLOOKUP(T30,Apoio!A:B,2,0),"") -> 1 | T30: =IFERROR(VLOOKUP(C30,'[1]TB DIN'!$B:$H,4,0),"AGUARDANDO ANEXO") -> 9 | U30: =IFERROR(VLOOKUP(C30,'[1]TB DIN INCLUIDOS'!$B:$H,4,0),"AGUARDANDO ANEXO") -> 0 | V30: {=_xlfn.IFS((U30>S30),(S30*2),(U30<=S30),(U30*2))} -> 0 | X30: =IFERROR(VLOOKUP(Y30,Apoio!A:B,2,0),"") -> 1 | Y30: 16 | Z30: =IFERROR(VLOOKUP(C30,'[1]TB DIN INCLUIDOS'!$B:$H,5,0),"AGUARDANDO ANEXO") -> 0 | AA30: {=_xlfn.IFS((Z30>X30),(X30*2),(Z30<=X30),(Z30*2))} -> 0 | AC30: =IFERROR(VLOOKUP(AD30,Apoio!A:B,2,0),"") -> 1 | AD30: 19 | AE30: =IFERROR(VLOOKUP(C30,'[1]TB DIN INCLUIDOS'!$B:$H,6,0),"AGUARDANDO ANEXO") -> 1 | AF30: {=_xlfn.IFS((AE30>AC30),(AC30*2),(AE30<=AC30),(AE30*2))} -> 2 | AH30: =SUM(O30,T30,Y30,AD30) -> 47 | AI30: =SUM(P30,U30,Z30,AE30) -> 1 | AJ30: =SUM(Q30,V30,AA30,AF30) -> 2 | AK30: =IF(L30-AH30-Q30-V30-AA30-AF30>0,L30-AH30-Q30-V30-AA30-AF30,0) -> 1 | AL30: =IF(L30-O30-Q30-T30-V30-Y30-AA30-AD30-AF30<0,L30-O30-Q30-T30-V30-Y30-AA30-AD30-AF30,0) -> 0 | AM30: manutenção | AN30: =VLOOKUP(C30,'[2]MARÇO-2024'!$B:$M,12,0) -> 46 | AO30: =AN30-AH30 -> -1 | AP30: =IF(AH30>L30,"Qt de aluno maior que a meta","")
A31: 2 | B31: 21 | C31: 2026 | D31: 33122377 | E31: 68696962000160 | F31: 020436 | G31: CP CRECHE MONSENHOR FRANCA | H31: CRECHE MONSENHOR FRANCA | I31: INSTITUTO MISSIONÁRIO COMUNHÃO E PARTICIPAÇÃO | J31: RUA TAVARES BASTOS, 296 | K31: CATETE | L31: 50 | N31: =IFERROR(VLOOKUP(O31,Apoio!A:B,2,0),"") | O31: =IFERROR(VLOOKUP(C31,'[1]TB DIN'!$B:$D,3,0),"AGUARDANDO ANEXO") -> 0 | P31: =IFERROR(VLOOKUP(C31,'[1]TB DIN INCLUIDOS'!$B:$H,3,0),"AGUARDANDO ANEXO") -> 0 | Q31: {=_xlfn.IFS((P31>N31),(N31*2),(P31<=N31),(P31*2))} -> 0 | S31: =IFERROR(VLOOKUP(T31,Apoio!A:B,2,0),"") | T31: =IFERROR(VLOOKUP(C31,'[1]TB DIN'!$B:$H,4,0),"AGUARDANDO ANEXO") -> 0 | U31: =IFERROR(VLOOKUP(C31,'[1]TB DIN INCLUIDOS'!$B:$H,4,0),"AGUARDANDO ANEXO") -> 0 | V31: {=_xlfn.IFS((U31>S31),(S31*2),(U31<=S31),(U31*2))} -> 0 | X31: =IFERROR(VLOOKUP(Y31,Apoio!A:B,2,0),"") -> 1 | Y31: 22 | Z31: =IFERROR(VLOOKUP(C31,'[1]TB DIN INCLUIDOS'!$B:$H,5,0),"AGUARDANDO ANEXO") -> 1 | AA31: {=_xlfn.IFS((Z31>X31),(X31*2),(Z31<=X31),(Z31*2))} -> 2 | AC31: =IFERROR(VLOOKUP(AD31,Apoio!A:B,2,0),"") -> 1 | AD31: =IFERROR(VLOOKUP(C31,'[1]TB DIN'!$B:$H,6,0),"AGUARDANDO ANEXO") -> 24 | AE31: 1 | AF31: {=_xlfn.IFS((AE31>AC31),(AC31*2),(AE31<=AC31),(AE31*2))} -> 2 | AH31: =SUM(O31,T31,Y31,AD31) -> 46 | AI31: =SUM(P31,U31,Z31,AE31) -> 2 | AJ31: =SUM(Q31,V31,AA31,AF31) -> 4 | AK31: =IF(L31-AH31-Q31-V31-AA31-AF31>0,L31-AH31-Q31-V31-AA31-AF31,0) -> 0 | AL31: =IF(L31-O31-Q31-T31-V31-Y31-AA31-AD31-AF31<0,L31-O31-Q31-T31-V31-Y31-AA31-AD31-AF31,0) -> 0 | AM31: manutenção | AN31: =VLOOKUP(C31,'[2]MARÇO-2024'!$B:$M,12,0) -> 44 | AO31: =AN31-AH31 -> -2 | AP31: =IF(AH31>L31,"Qt de aluno maior que a meta","")
A32: 2 | B32: 22 | C32: 2028 | D32: 33122610 | E32: 34021568000100 | F32: 020464 | G32: CP OBRAS SOCIAIS PADRE ALEIXO | H32: OBRAS SOCIAIS PADRE ALEIXO | I32: MITRA ARQUIEPISCOPAL DO RIO DE JANEIRO | J32: RUA PAULO VI, 62 | K32: FLAMENGO | L32: 90 | N32: =IFERROR(VLOOKUP(O32,Apoio!A:B,2,0),"") | O32: =IFERROR(VLOOKUP(C32,'[1]TB DIN'!$B:$D,3,0),"AGUARDANDO ANEXO") -> 0 | P32: =IFERROR(VLOOKUP(C32,'[1]TB DIN INCLUIDOS'!$B:$H,3,0),"AGUARDANDO ANEXO") -> 0 | Q32: {=_xlfn.IFS((P32>N32),(N32*2),(P32<=N32),(P32*2))} -> 0 | S32: =IFERROR(VLOOKUP(T32,Apoio!A:B,2,0),"") -> 2 | T32: 32 | U32: =IFERROR(VLOOKUP(C32,'[1]TB DIN INCLUIDOS'!$B:$H,4,0),"AGUARDANDO ANEXO") -> 0 | V32: {=_xlfn.IFS((U32>S32),(S32*2),(U32<=S32),(U32*2))} -> 0 | X32: =IFERROR(VLOOKUP(Y32,Apoio!A:B,2,0),"") -> 2 | Y32: =IFERROR(VLOOKUP(C32,'[1]TB DIN'!$B:$H,5,0),"AGUARDANDO ANEXO") -> 26 | Z32: =IFERROR(VLOOKUP(C32,'[1]TB DIN INCLUIDOS'!$B:$H,5,0),"AGUARDANDO ANEXO") -> 0 | AA32: {=_xlfn.IFS((Z32>X32),(X32*2),(Z32<=X32),(Z32*2))} -> 0 | AC32: =IFERROR(VLOOKUP(AD32,Apoio!A:B,2,0),"") -> 2 | AD32: 31 | AE32: =IFERROR(VLOOKUP(C32,'[1]TB DIN INCLUIDOS'!$B:$H,6,0),"AGUARDANDO ANEXO") -> 1 | AF32: {=_xlfn.IFS((AE32>AC32),(AC32*2),(AE32<=AC32),(AE32*2))} -> 2 | AH32: =SUM(O32,T32,Y32,AD32) -> 89 | AI32: =SUM(P32,U32,Z32,AE32) -> 1 | AJ32: =SUM(Q32,V32,AA32,AF32) -> 2 | AK32: =IF(L32-AH32-Q32-V32-AA32-AF32>0,L32-AH32-Q32-V32-AA32-AF32,0) -> 0 | AL32: =IF(L32-O32-Q32-T32-V32-Y32-AA32-AD32-AF32<0,L32-O32-Q32-T32-V32-Y32-AA32-AD32-AF32,0) -> -1 | AM32: manutenção | AN32: =VLOOKUP(C32,'[2]MARÇO-2024'!$B:$M,12,0) -> 84 | AO32: =AN32-AH32 -> -5 | AP32: =IF(AH32>L32,"Qt de aluno maior que a meta","")
A33: 2 | B33: 23 | C33: 2029 | D33: 33122695 | E33: 33904020000146 | F33: 020456 | G33: CP CASA DA CRIANÇA | H33: CASA DA CRIANÇA | I33: CASA DA CRIANÇA | J33: RUA FERNANDES GUIMARÃES, 85 | K33: BOTAFOGO | L33: 192 | N33: =IFERROR(VLOOKUP(O33,Apoio!A:B,2,0),"") -> 1 | O33: =IFERROR(VLOOKUP(C33,'[1]TB DIN'!$B:$D,3,0),"AGUARDANDO ANEXO") -> 12 | P33: =IFERROR(VLOOKUP(C33,'[1]TB DIN INCLUIDOS'!$B:$H,3,0),"AGUARDANDO ANEXO") -> 0 | Q33: {=_xlfn.IFS((P33>N33),(N33*2),(P33<=N33),(P33*2))} -> 0 | S33: =IFERROR(VLOOKUP(T33,Apoio!A:B,2,0),"") -> 2 | T33: 39 | U33: =IFERROR(VLOOKUP(C33,'[1]TB DIN INCLUIDOS'!$B:$H,4,0),"AGUARDANDO ANEXO") -> 0 | V33: {=_xlfn.IFS((U33>S33),(S33*2),(U33<=S33),(U33*2))} -> 0 | X33: =IFERROR(VLOOKUP(Y33,Apoio!A:B,2,0),"") -> 3 | Y33: =IFERROR(VLOOKUP(C33,'[1]TB DIN'!$B:$H,5,0),"AGUARDANDO ANEXO") -> 67 | Z33: =IFERROR(VLOOKUP(C33,'[1]TB DIN INCLUIDOS'!$B:$H,5,0),"AGUARDANDO ANEXO") -> 2 | AA33: {=_xlfn.IFS((Z33>X33),(X33*2),(Z33<=X33),(Z33*2))} -> 4 | AC33: =IFERROR(VLOOKUP(AD33,Apoio!A:B,2,0),"") -> 3 | AD33: 70 | AE33: 3 | AF33: {=_xlfn.IFS((AE33>AC33),(AC33*2),(AE33<=AC33),(AE33*2))} -> 6 | AH33: =SUM(O33,T33,Y33,AD33) -> 188 | AI33: =SUM(P33,U33,Z33,AE33) -> 5 | AJ33: =SUM(Q33,V33,AA33,AF33) -> 10 | AK33: =IF(L33-AH33-Q33-V33-AA33-AF33>0,L33-AH33-Q33-V33-AA33-AF33,0) -> 0 | AL33: =IF(L33-O33-Q33-T33-V33-Y33-AA33-AD33-AF33<0,L33-O33-Q33-T33-V33-Y33-AA33-AD33-AF33,0) -> -6 | AM33: manutenção | AN33: =VLOOKUP(C33,'[2]MARÇO-2024'!$B:$M,12,0) -> 189 | AO33: =AN33-AH33 -> 1 | AP33: =IF(AH33>L33,"Qt de aluno maior que a meta","")
A34: 2 | B34: 24 | C34: 2031 | D34: 33122890 | E34: 28019248000113 | F34: 020435 | G34: CP CENTRO COMUNITÁRIO ALEGRIA DAS CRIANÇAS | H34: CENTRO COMUNITÁRIO ALEGRIA DAS CRIANÇAS | I34: CENTRO COMUNITÁRIO ALEGRIA DAS CRIANÇAS | J34: RUA DOIS, 431 | K34: ROCINHA | L34: 88 | N34: =IFERROR(VLOOKUP(O34,Apoio!A:B,2,0),"") | O34: =IFERROR(VLOOKUP(C34,'[1]TB DIN'!$B:$D,3,0),"AGUARDANDO ANEXO") -> 0 | P34: =IFERROR(VLOOKUP(C34,'[1]TB DIN INCLUIDOS'!$B:$H,3,0),"AGUARDANDO ANEXO") -> 0 | Q34: {=_xlfn.IFS((P34>N34),(N34*2),(P34<=N34),(P34*2))} -> 0 | S34: =IFERROR(VLOOKUP(T34,Apoio!A:B,2,0),"") -> 1 | T34: 1 | U34: =IFERROR(VLOOKUP(C34,'[1]TB DIN INCLUIDOS'!$B:$H,4,0),"AGUARDANDO ANEXO") -> 0 | V34: {=_xlfn.IFS((U34>S34),(S34*2),(U34<=S34),(U34*2))} -> 0 | X34: =IFERROR(VLOOKUP(Y34,Apoio!A:B,2,0),"") -> 2 | Y34: 36 | Z34: =IFERROR(VLOOKUP(C34,'[1]TB DIN INCLUIDOS'!$B:$H,5,0),"AGUARDANDO ANEXO") -> 0 | AA34: {=_xlfn.IFS((Z34>X34),(X34*2),(Z34<=X34),(Z34*2))} -> 0 | AC34: =IFERROR(VLOOKUP(AD34,Apoio!A:B,2,0),"") -> 3 | AD34: =IFERROR(VLOOKUP(C34,'[1]TB DIN'!$B:$H,6,0),"AGUARDANDO ANEXO") -> 51 | AE34: =IFERROR(VLOOKUP(C34,'[1]TB DIN INCLUIDOS'!$B:$H,6,0),"AGUARDANDO ANEXO") -> 1 | AF34: {=_xlfn.IFS((AE34>AC34),(AC34*2),(AE34<=AC34),(AE34*2))} -> 2 | AH34: =SUM(O34,T34,Y34,AD34) -> 88 | AI34: =SUM(P34,U34,Z34,AE34) -> 1 | AJ34: =SUM(Q34,V34,AA34,AF34) -> 2 | AK34: =IF(L34-AH34-Q34-V34-AA34-AF34>0,L34-AH34-Q34-V34-AA34-AF34,0) -> 0 | AL34: =IF(L34-O34-Q34-T34-V34-Y34-AA34-AD34-AF34<0,L34-O34-Q34-T34-V34-Y34-AA34-AD34-AF34,0) -> -2 | AM34: manutenção c/ aumento de meta | AN34: =VLOOKUP(C34,'[2]MARÇO-2024'!$B:$M,12,0) -> 88 | AO34: =AN34-AH34 -> 0 | AP34: =IF(AH34>L34,"Qt de aluno maior que a meta","")
A35: 2 | B35: 25 | C35: 2032 | D35: 33122954 | E35: 34068528000114 | F35: 020465 | G35: CP PATRONATO OPERÁRIO DA GÁVEA | H35: PATRONATO OPERÁRIO DA GÁVEA | I35: PATRONATO OPERÁRIO DA GÁVEA | J35: AV. LINEU DE PAULA MACHADO, 795 | K35: GÁVEA | L35: 80 | N35: =IFERROR(VLOOKUP(O35,Apoio!A:B,2,0),"") | O35: =IFERROR(VLOOKUP(C35,'[1]TB DIN'!$B:$D,3,0),"AGUARDANDO ANEXO") -> 0 | P35: =IFERROR(VLOOKUP(C35,'[1]TB DIN INCLUIDOS'!$B:$H,3,0),"AGUARDANDO ANEXO") -> 0 | Q35: {=_xlfn.IFS((P35>N35),(N35*2),(P35<=N35),(P35*2))} -> 0 | S35: =IFERROR(VLOOKUP(T35,Apoio!A:B,2,0),"") | T35: =IFERROR(VLOOKUP(C35,'[1]TB DIN'!$B:$H,4,0),"AGUARDANDO ANEXO") -> 0 | U35: =IFERROR(VLOOKUP(C35,'[1]TB DIN INCLUIDOS'!$B:$H,4,0),"AGUARDANDO ANEXO") -> 0 | V35: {=_xlfn.IFS((U35>S35),(S35*2),(U35<=S35),(U35*2))} -> 0 | X35: =IFERROR(VLOOKUP(Y35,Apoio!A:B,2,0),"") -> 2 | Y35: =IFERROR(VLOOKUP(C35,'[1]TB DIN'!$B:$H,5,0),"AGUARDANDO ANEXO") -> 29 | Z35: =IFERROR(VLOOKUP(C35,'[1]TB DIN INCLUIDOS'!$B:$H,5,0),"AGUARDANDO ANEXO") -> 0 | AA35: {=_xlfn.IFS((Z35>X35),(X35*2),(Z35<=X35),(Z35*2))} -> 0 | AC35: =IFERROR(VLOOKUP(AD35,Apoio!A:B,2,0),"") -> 2 | AD35: 42 | AE35: 3 | AF35: {=_xlfn.IFS((AE35>AC35),(AC35*2),(AE35<=AC35),(AE35*2))} -> 4 | AH35: =SUM(O35,T35,Y35,AD35) -> 71 | AI35: =SUM(P35,U35,Z35,AE35) -> 3 | AJ35: =SUM(Q35,V35,AA35,AF35) -> 4 | AK35: =IF(L35-AH35-Q35-V35-AA35-AF35>0,L35-AH35-Q35-V35-AA35-AF35,0) -> 5 | AL35: =IF(L35-O35-Q35-T35-V35-Y35-AA35-AD35-AF35<0,L35-O35-Q35-T35-V35-Y35-AA35-AD35-AF35,0) -> 0 | AM35: manutenção | AN35: =VLOOKUP(C35,'[2]MARÇO-2024'!$B:$M,12,0) -> 70 | AO35: =AN35-AH35 -> -1 | AP35: =IF(AH35>L35,"Qt de aluno maior que a meta","")
A36: 2 | B36: 26 | C36: 2034 | D36: 33152004 | E36: 04697185000196 | F36: 020445 | G36: CP CENTRO SOCIAL DA MULHER UÊGA | H36: CENTRO SOCIAL DA MULHER UÊGA | I36: CENTRO SOCIAL DA MULHER UÊGA | J36: RUA ESPERANÇA, 37 - 2º ANDAR | K36: ROCINHA | L36: 100 | N36: =IFERROR(VLOOKUP(O36,Apoio!A:B,2,0),"") | O36: =IFERROR(VLOOKUP(C36,'[1]TB DIN'!$B:$D,3,0),"AGUARDANDO ANEXO") -> 0 | P36: =IFERROR(VLOOKUP(C36,'[1]TB DIN INCLUIDOS'!$B:$H,3,0),"AGUARDANDO ANEXO") -> 0 | Q36: {=_xlfn.IFS((P36>N36),(N36*2),(P36<=N36),(P36*2))} -> 0 | S36: =IFERROR(VLOOKUP(T36,Apoio!A:B,2,0),"") | T36: =IFERROR(VLOOKUP(C36,'[1]TB DIN'!$B:$H,4,0),"AGUARDANDO ANEXO") -> 0 | U36: =IFERROR(VLOOKUP(C36,'[1]TB DIN INCLUIDOS'!$B:$H,4,0),"AGUARDANDO ANEXO") -> 0 | V36: {=_xlfn.IFS((U36>S36),(S36*2),(U36<=S36),(U36*2))} -> 0 | X36: =IFERROR(VLOOKUP(Y36,Apoio!A:B,2,0),"") -> 2 | Y36: 40 | Z36: =IFERROR(VLOOKUP(C36,'[1]TB DIN INCLUIDOS'!$B:$H,5,0),"AGUARDANDO ANEXO") -> 1 | AA36: {=_xlfn.IFS((Z36>X36),(X36*2),(Z36<=X36),(Z36*2))} -> 2 | AC36: =IFERROR(VLOOKUP(AD36,Apoio!A:B,2,0),"") -> 3 | AD36: 54 | AE36: =IFERROR(VLOOKUP(C36,'[1]TB DIN INCLUIDOS'!$B:$H,6,0),"AGUARDANDO ANEXO") -> 1 | AF36: {=_xlfn.IFS((AE36>AC36),(AC36*2),(AE36<=AC36),(AE36*2))} -> 2 | AH36: =SUM(O36,T36,Y36,AD36) -> 94 | AI36: =SUM(P36,U36,Z36,AE36) -> 2 | AJ36: =SUM(Q36,V36,AA36,AF36) -> 4 | AK36: =IF(L36-AH36-Q36-V36-AA36-AF36>0,L36-AH36-Q36-V36-AA36-AF36,0) -> 2 | AL36: =IF(L36-O36-Q36-T36-V36-Y36-AA36-AD36-AF36<0,L36-O36-Q36-T36-V36-Y36-AA36-AD36-AF36,0) -> 0 | AM36: manutenção | AN36: =VLOOKUP(C36,'[2]MARÇO-2024'!$B:$M,12,0) -> 94 | AO36: =AN36-AH36 -> 0 | AP36: =IF(AH36>L36,"Qt de aluno maior que a meta","")
